Workbook

Sheet Sheet5

Sheet Sheet4

Sheet 企
B1: 期間１０月２５日～６月１１日 | J1: 砂目標：２５０～３００ｇ 好記録：４００ｇ～ | N1: 統計
B2: 企業名 | C2: 品種名 | D2: 正規品（ｇ） | E2: 加工用（ｇ） | F2: パック数 | G2: 収穫量（ｇ） | H2: 株数 | I2: 面積（㎡） | J2: １株あたり収量（ｇ） | K2: 歩留まり（％） | L2: 加工比率（％） | M2: 10aあたり収量（kg） | N2: 偏差 | O2: 正規品（ｇ） | P2: 加工用（ｇ） | Q2: パック数 | R2: 収穫量（ｇ） | S2: 株数 | T2: 面積（㎡） | U2: １株あたり収量（ｇ） | V2: 歩留まり（％） | W2: 加工比率（％） | X2: 10aあたり収量（g）
B3: マルテー | C3: 4種 | D3: =SUM(企収!D3:D113) -> 61457 | E3: =SUM(企収!E3:E113) -> 51090 | F3: =SUM(企収!F3:F113) -> 417 | G3: =SUM(D3:E3) -> 112547 | H3: 450 | I3: =0.3*14*6 -> 25.2 | J3: =G3/H3 -> 250.10444 | K3: =(D3/G3)*100 -> 54.605631 | L3: =E3 / G3 * 100 -> 45.394369 | M3: =G3 / I3 * 100 / 1000 -> 446.61508 | O3: =D3-22665 -> 38792 | P3: =E3-15218 -> 35872 | Q3: =F3-160 -> 257 | R3: =G3-37882 -> 74665 | S3: =H3-217 -> 233 | T3: =I3-13 -> 12.2 | U3: =J3-153.9 -> 96.204444 | V3: =K3-60 -> -5.3943686 | W3: =L3-40 -> 5.3943686 | X3: =M3-246.72 -> 199.89508
B4: 三和 | C4: 紅ほっぺ | D4: =SUM(企収!J3:J17) -> 2616 | E4: =SUM(企収!K3:K17) -> 2900 | F4: =SUM(企収!L3:L17) -> 9 | G4: =SUM(D4:E4) -> 5516 | H4: 80 | I4: =0.3*28 -> 8.4 | J4: =G4/H4 -> 68.95 | K4: =(D4/G4)*100 -> 47.425671 | L4: =E4 / G4 * 100 -> 52.574329 | M4: =G4 / I4 * 100 / 1000 -> 65.666667 | O4: =D4-22665 -> -20049 | P4: =E4-15218 -> -12318 | Q4: =F4-160 -> -151 | R4: =G4-37882 -> -32366 | S4: =H4-217 -> -137 | T4: =I4-13 -> -4.6 | U4: =J4-153.9 -> -84.95 | V4: =K4-60 -> -12.574329 | W4: =L4-40 -> 12.574329 | X4: =M4-246.72 -> -181.05333
B5: QB | C5: 紅ほっぺ | D5: =SUM(企収!P3:P23) -> 4527 | E5: =SUM(企収!Q3:Q23) -> 2536 | F5: =SUM(企収!R3:R23) -> 25 | G5: =SUM(D5:E5) -> 7063 | H5: 80 | I5: =0.3*28 -> 8.4 | J5: =G5/H5 -> 88.2875 | K5: =(D5/G5)*100 -> 64.094577 | L5: =E5 / G5 * 100 -> 35.905423 | M5: =G5 / I5 * 100 / 1000 -> 84.083333 | O5: =D5-22665 -> -18138 | P5: =E5-15218 -> -12682 | Q5: =F5-160 -> -135 | R5: =G5-37882 -> -30819 | S5: =H5-217 -> -137 | T5: =I5-13 -> -4.6 | U5: =J5-153.9 -> -65.6125 | V5: =K5-60 -> 4.0945774 | W5: =L5-40 -> -4.0945774 | X5: =M5-246.72 -> -162.63667
B6: 東レ（計） | C6: 紅ほっぺ＋よつぼし | D6: =SUM(企収!V3:V48) -> 77893 | E6: =SUM(企収!W3:W48) -> 58668 | F6: =SUM(企収!X3:X48) -> 478 | G6: =SUM(D6:E6) -> 136561 | H6: 640 | I6: 34 | J6: =G6/H6 -> 213.37656 | K6: =(D6/G6)*100 -> 57.038979 | L6: =E6 / G6 * 100 -> 42.961021 | M6: =G6 / I6 * 100 / 1000 -> 401.65 | O6: =D6-22665 -> 55228 | P6: =E6-15218 -> 43450 | Q6: =F6-160 -> 318 | R6: =G6-37882 -> 98679 | S6: =H6-217 -> 423 | T6: =I6-13 -> 21 | U6: =J6-153.9 -> 59.476562 | V6: =K6-60 -> -2.9610211 | W6: =L6-40 -> 2.9610211 | X6: =M6-246.72 -> 154.93
B7: Adobe | C7: かおりの | D7: =SUM(企収!AB3:AB28) -> 42160 | E7: =SUM(企収!AC3:AC28) -> 18930 | F7: =SUM(企収!AD3:AD28) -> 323 | G7: =SUM(D7:E7) -> 61090 | H7: 320 | I7: =0.3*28*2 -> 16.8 | J7: =G7/H7 -> 190.90625 | K7: =(D7/G7)*100 -> 69.012932 | L7: =E7 / G7 * 100 -> 30.987068 | M7: =G7 / I7 * 100 / 1000 -> 363.63095 | O7: =D7-22665 -> 19495 | P7: =E7-15218 -> 3712 | Q7: =F7-160 -> 163 | R7: =G7-37882 -> 23208 | S7: =H7-217 -> 103 | T7: =I7-13 -> 3.8 | U7: =J7-153.9 -> 37.00625 | V7: =K7-60 -> 9.0129317 | W7: =L7-40 -> -9.0129317 | X7: =M7-246.72 -> 116.91095
B8: バリュ（計） | C8: 紅ほっぺ＋やよいひめ | D8: =SUM(企収!AH3:AH42) -> 28882 | E8: =SUM(企収!AI3:AI42) -> 15983 | F8: =SUM(企収!AJ3:AJ42) -> 210 | G8: =SUM(D8:E8) -> 44865 | H8: 320 | I8: 26 | J8: =G8/H8 -> 140.20312 | K8: =(D8/G8)*100 -> 64.375348 | L8: =E8 / G8 * 100 -> 35.624652 | M8: =G8 / I8 * 100 / 1000 -> 172.55769 | O8: =D8-22665 -> 6217 | P8: =E8-15218 -> 765 | Q8: =F8-160 -> 50 | R8: =G8-37882 -> 6983 | S8: =H8-217 -> 103 | T8: =I8-13 -> 13 | U8: =J8-153.9 -> -13.696875 | V8: =K8-60 -> 4.3753483 | W8: =L8-40 -> -4.3753483 | X8: =M8-246.72 -> -74.162308
B9: ソリトン | C9: 紅ほっぺ | D9: =SUM(企収!AN3:AN24) -> 12480 | E9: =SUM(企収!AO3:AO24) -> 5707 | F9: =SUM(企収!AP3:AP24) -> 92 | G9: =SUM(D9:E9) -> 18187 | H9: 80 | I9: =0.3*28 -> 8.4 | J9: =G9/H9 -> 227.3375 | K9: =(D9/G9)*100 -> 68.620443 | L9: =E9 / G9 * 100 -> 31.379557 | M9: =G9 / I9 * 100 / 1000 -> 216.5119 | O9: =D9-22665 -> -10185 | P9: =E9-15218 -> -9511 | Q9: =F9-160 -> -68 | R9: =G9-37882 -> -19695 | S9: =H9-217 -> -137 | T9: =I9-13 -> -4.6 | U9: =J9-153.9 -> 73.4375 | V9: =K9-60 -> 8.6204432 | W9: =L9-40 -> -8.6204432 | X9: =M9-246.72 -> -30.208095
B10: NaITO | C10: 紅ほっぺ | D10: =SUM(企収!AT3:AT25) -> 9595 | E10: =SUM(企収!AU3:AU25) -> 7843 | F10: =SUM(企収!AV3:AV25) -> 66 | G10: =SUM(D10:E10) -> 17438 | H10: 80 | I10: 4 | J10: =G10/H10 -> 217.975 | K10: =(D10/G10)*100 -> 55.023512 | L10: =E10 / G10 * 100 -> 44.976488 | M10: =G10 / I10 * 100 / 1000 -> 435.95 | O10: =D10-22665 -> -13070 | P10: =E10-15218 -> -7375 | Q10: =F10-160 -> -94 | R10: =G10-37882 -> -20444 | S10: =H10-217 -> -137 | T10: =I10-13 -> -9 | U10: =J10-153.9 -> 64.075 | V10: =K10-60 -> -4.9764881 | W10: =L10-40 -> 4.9764881 | X10: =M10-246.72 -> 189.23
B11: 岡部 | C11: 紅ほっぺ | D11: =SUM(企収!AZ3:AZ19) -> 4630 | E11: =SUM(企収!BA3:BA19) -> 3524 | F11: =SUM(企収!BB3:BB19) -> 47 | G11: =SUM(D11:E11) -> 8154 | H11: 80 | I11: =0.3*28 -> 8.4 | J11: =G11/H11 -> 101.925 | K11: =(D11/G11)*100 -> 56.781948 | L11: =E11 / G11 * 100 -> 43.218052 | M11: =G11 / I11 * 100 / 1000 -> 97.071429 | O11: =D11-22665 -> -18035 | P11: =E11-15218 -> -11694 | Q11: =F11-160 -> -113 | R11: =G11-37882 -> -29728 | S11: =H11-217 -> -137 | T11: =I11-13 -> -4.6 | U11: =J11-153.9 -> -51.975 | V11: =K11-60 -> -3.2180525 | W11: =L11-40 -> 3.2180525 | X11: =M11-246.72 -> -149.64857
B12: ケイアイ | C12: 紅ほっぺ | D12: =SUM(企収!BF3:BF24) -> 26392 | E12: =SUM(企収!BG3:BG24) -> 9091 | F12: =SUM(企収!BH3:BH24) -> 198 | G12: =SUM(D12:E12) -> 35483 | H12: 240 | I12: =0.3*28 -> 8.4 | J12: =G12/H12 -> 147.84583 | K12: =(D12/G12)*100 -> 74.37928 | L12: =E12 / G12 * 100 -> 25.62072 | M12: =G12 / I12 * 100 / 1000 -> 422.41667 | O12: =D12-22665 -> 3727 | P12: =E12-15218 -> -6127 | Q12: =F12-160 -> 38 | R12: =G12-37882 -> -2399 | S12: =H12-217 -> 23 | T12: =I12-13 -> -4.6 | U12: =J12-153.9 -> -6.0541667 | V12: =K12-60 -> 14.37928 | W12: =L12-40 -> -14.37928 | X12: =M12-246.72 -> 175.69667
B13: 富士機械 | C13: やよいひめ | D13: =SUM(企収!BL3:BL22) -> 25250 | E13: =SUM(企収!BM3:BM22) -> 22378 | F13: =SUM(企収!BN3:BN22) -> 224 | G13: =SUM(D13:E13) -> 47628 | H13: 320 | I13: =0.3*28*2 -> 16.8 | J13: =G13/H13 -> 148.8375 | K13: =(D13/G13)*100 -> 53.015033 | L13: =E13 / G13 * 100 -> 46.984967 | M13: =G13 / I13 * 100 / 1000 -> 283.5 | O13: =D13-22665 -> 2585 | P13: =E13-15218 -> 7160 | Q13: =F13-160 -> 64 | R13: =G13-37882 -> 9746 | S13: =H13-217 -> 103 | T13: =I13-13 -> 3.8 | U13: =J13-153.9 -> -5.0625 | V13: =K13-60 -> -6.9849668 | W13: =L13-40 -> 6.9849668 | X13: =M13-246.72 -> 36.78
B14: 慈誠会 | C14: 紅ほっぺ | D14: =SUM(企収!BR3:BR22) -> 6730 | E14: =SUM(企収!BS3:BS22) -> 4350 | F14: =SUM(企収!BT3:BT22) -> 48 | G14: =SUM(D14:E14) -> 11080 | H14: 80 | I14: =0.3*28 -> 8.4 | J14: =G14/H14 -> 138.5 | K14: =(D14/G14)*100 -> 60.740072 | L14: =E14 / G14 * 100 -> 39.259928 | M14: =G14 / I14 * 100 / 1000 -> 131.90476 | O14: =D14-22665 -> -15935 | P14: =E14-15218 -> -10868 | Q14: =F14-160 -> -112 | R14: =G14-37882 -> -26802 | S14: =H14-217 -> -137 | T14: =I14-13 -> -4.6 | U14: =J14-153.9 -> -15.4 | V14: =K14-60 -> 0.7400722 | W14: =L14-40 -> -0.7400722 | X14: =M14-246.72 -> -114.81524
B15: 富士機材 | C15: やよいひめ | D15: =SUM(企収!BX3:BX23) -> 26528 | E15: =SUM(企収!BY3:BY23) -> 17042 | F15: =SUM(企収!BZ3:BZ23) -> 179 | G15: =SUM(D15:E15) -> 43570 | H15: 320 | I15: =0.3*28*2 -> 16.8 | J15: =G15/H15 -> 136.15625 | K15: =(D15/G15)*100 -> 60.885931 | L15: =E15 / G15 * 100 -> 39.114069 | M15: =G15 / I15 * 100 / 1000 -> 259.34524 | O15: =D15-22665 -> 3863 | P15: =E15-15218 -> 1824 | Q15: =F15-160 -> 19 | R15: =G15-37882 -> 5688 | S15: =H15-217 -> 103 | T15: =I15-13 -> 3.8 | U15: =J15-153.9 -> -17.74375 | V15: =K15-60 -> 0.88593069 | W15: =L15-40 -> -0.88593069 | X15: =M15-246.72 -> 12.625238
B16: 昭和女子 | C16: 紅ほっぺ | D16: =SUM(企収!CD3:CD26) -> 6230 | E16: =SUM(企収!CE3:CE26) -> 5714 | F16: =SUM(企収!CF3:CF26) -> 42 | G16: =SUM(D16:E16) -> 11944 | H16: 80 | I16: =0.3*28 -> 8.4 | J16: =G16/H16 -> 149.3 | K16: =(D16/G16)*100 -> 52.16008 | L16: =E16 / G16 * 100 -> 47.83992 | M16: =G16 / I16 * 100 / 1000 -> 142.19048 | O16: =D16-22665 -> -16435 | P16: =E16-15218 -> -9504 | Q16: =F16-160 -> -118 | R16: =G16-37882 -> -25938 | S16: =H16-217 -> -137 | T16: =I16-13 -> -4.6 | U16: =J16-153.9 -> -4.6 | V16: =K16-60 -> -7.8399196 | W16: =L16-40 -> 7.8399196 | X16: =M16-246.72 -> -104.52952
B17: 日建 | C17: 紅ほっぺ | D17: =SUM(企収!CJ3:CJ18) -> 4600 | E17: =SUM(企収!CK3:CK18) -> 2509 | F17: =SUM(企収!CL3:CL18) -> 41 | G17: =SUM(D17:E17) -> 7109 | H17: 80 | I17: 4 | J17: =G17/H17 -> 88.8625 | K17: =(D17/G17)*100 -> 64.70671 | L17: =E17 / G17 * 100 -> 35.29329 | M17: =G17 / I17 * 100 / 1000 -> 177.725 | O17: =D17-22665 -> -18065 | P17: =E17-15218 -> -12709 | Q17: =F17-160 -> -119 | R17: =G17-37882 -> -30773 | S17: =H17-217 -> -137 | T17: =I17-13 -> -9 | U17: =J17-153.9 -> -65.0375 | V17: =K17-60 -> 4.7067098 | W17: =L17-40 -> -4.7067098 | X17: =M17-246.72 -> -68.995
B18: 代表値 | C18: 合計 | D18: =SUM(D3:D17) -> 339970 | E18: =SUM(E3:E17) -> 228265 | F18: =SUM(F3:F17) -> 2399 | G18: =SUM(G3:G17) -> 568235 | H18: =SUM(H3:H17) -> 3250 | I18: =SUM(I3:I17) -> 202.4 | N18: 分散 | O18: {=SUM(O3:O17*O3:O17)/COUNT(O3:O17)} -> 479353357 | P18: {=SUM(P3:P17*P3:P17)/COUNT(P3:P17)} -> 2.8302157e+08 | Q18: {=SUM(Q3:Q17*Q3:Q17)/COUNT(Q3:Q17)} -> 20668.467 | R18: {=SUM(R3:R17*R3:R17)/COUNT(R3:R17)} -> 1.4705301e+09 | S18: {=SUM(S3:S17*S3:S17)/COUNT(S3:S17)} -> 28422.333 | T18: {=SUM(T3:T17*T3:T17)/COUNT(T3:T17)} -> 74.152 | U18: {=SUM(U3:U17*U3:U17)/COUNT(U3:U17)} -> 2862.4479 | V18: {=SUM(V3:V17*V3:V17)/COUNT(V3:V17)} -> 50.870642 | ... X18: {=SUM(X3:X17*X3:X17)/COUNT(X3:X17)} -> 17515.102
C19: 中央値 | D19: =MEDIAN(D3:D17) -> 12480 | E19: =MEDIAN(E3:E17) -> 7843 | F19: =MEDIAN(F3:F17) -> 92 | G19: =MEDIAN(G3:G17) -> 18187 | H19: =MEDIAN(H3:H17) -> 80 | I19: =MEDIAN(I3:I17) -> 8.4 | J19: =MEDIAN(J3:J17) -> 147.84583 | K19: =MEDIAN(K3:K17) -> 60.740072 | ... M19: =MEDIAN(M3:M17) -> 216.5119 | N19: 標準偏差 | O19: =SQRT(O18) -> 21894.14 | P19: =SQRT(P18) -> 16823.245 | Q19: =SQRT(Q18) -> 143.76532 | R19: =SQRT(R18) -> 38347.491 | S19: =SQRT(S18) -> 168.58924 | T19: =SQRT(T18) -> 8.6111556 | U19: =SQRT(U18) -> 53.501849 | V19: =SQRT(V18) -> 7.1323658 | ... X19: =SQRT(X18) -> 132.34463
C20: 最大値 | D20: =MAX(D3:D17) -> 77893 | E20: =MAX(E3:E17) -> 58668 | F20: =MAX(F3:F17) -> 478 | G20: =MAX(G3:G17) -> 136561 | H20: =MAX(H3:H17) -> 640 | I20: =MAX(I3:I17) -> 34 | J20: =MAX(J3:J17) -> 250.10444 | K20: =MAX(K3:K17) -> 74.37928 | ... M20: =MAX(M3:M17) -> 446.61508
C21: 最小値 | D21: =MIN(D3:D17) -> 2616 | E21: =MIN(E3:E17) -> 2509 | F21: =MIN(F3:F17) -> 9 | G21: =MIN(G3:G17) -> 5516 | H21: =MIN(H3:H17) -> 80 | I21: =MIN(I3:I17) -> 4 | J21: =MIN(J3:J17) -> 68.95 | K21: =MIN(K3:K17) -> 47.425671 | ... M21: =MIN(M3:M17) -> 65.666667
C22: 平均 | D22: =AVERAGE(D3:D17) -> 22664.667 | E22: =AVERAGE(E3:E17) -> 15217.667 | F22: =AVERAGE(F3:F17) -> 159.93333 | G22: =AVERAGE(G3:G17) -> 37882.333 | H22: =AVERAGE(H3:H17) -> 216.66667 | I22: =AVERAGE(I3:I17) -> 13.493333 | J22: =AVERAGE(J3:J17) -> 153.9045 | K22: =AVERAGE(K3:K17) -> 60.191077 | ... M22: =AVERAGE(M3:M17) -> 246.72128 | O22: 偏差：
C23: 中央値： | O23: 平均－データの値でデータのばらつきを表す
C24: 複数品種・複数区画の収量データに外れ値がある場合、平均より中央値のほうが代表値として信頼できるので役立ちます。
O25: 分散：
O26: 偏差を2乗して平均をとる。データのばらつきの大きさの指標
O28: 標準偏差：
O29: 分散を平方根する。分散の値を標準化してデータのばらつきを示す

Sheet Sheet2
A1: 企業名 | B1: 正規品（ｋｇ） | C1: 収穫量（ｋｇ） | D1: １株収量（ｇ） | E1: 歩留まり（％） | F1: パック数 | G1: 株数
A2: マルテー | B2: 61.45 | C2: 112.54 | D2: 250.10444 | E2: 54.605631 | F2: 417 | G2: 450
A3: 三和 | B3: 2.61 | C3: 5.51 | D3: 68.95 | E3: 47.425671 | F3: 9 | G3: 80
A4: QB | B4: 4.52 | C4: 7.06 | D4: 88.2875 | E4: 64.094577 | F4: 25 | G4: 80
A5: 東レ（計） | B5: 77.89 | C5: 136.56 | D5: 213.37656 | E5: 57.038979 | F5: 478 | G5: 640
A6: Adobe | B6: 42.16 | C6: 61.09 | D6: 190.90625 | E6: 69.012932 | F6: 323 | G6: 320
A7: バリュ（計） | B7: 28.88 | C7: 44.86 | D7: 140.20312 | E7: 64.375348 | F7: 210 | G7: 320
A8: ソリトン | B8: 12.48 | C8: 18.18 | D8: 227.3375 | E8: 68.620443 | F8: 92 | G8: 80
A9: NaITO | B9: 9.59 | C9: 17.43 | D9: 217.975 | E9: 55.023512 | F9: 66 | G9: 80
A10: 岡部 | B10: 4.63 | C10: 8.15 | D10: 101.925 | E10: 56.781948 | F10: 47 | G10: 80
A11: ケイアイ | B11: 26.39 | C11: 35.48 | D11: 147.84583 | E11: 74.37928 | F11: 198 | G11: 240
A12: 富士機械 | B12: 25.25 | C12: 47.62 | D12: 148.8375 | E12: 53.015033 | F12: 224 | G12: 320
A13: 慈誠会 | B13: 6.73 | C13: 11.08 | D13: 138.5 | E13: 60.740072 | F13: 48 | G13: 80
... A16: 日建 | B16: 4.6 | C16: 7.11 | D16: 88.8625 | E16: 64.70671 | F16: 41 | G16: 80
B17: =AVERAGE(B2:B16) -> 22.662 | C17: =AVERAGE(C2:C16) -> 37.878667 | D17: =AVERAGE(D2:D16) -> 153.9045 | E17: =AVERAGE(E2:E16) -> 60.191077 | F17: =AVERAGE(F2:F16) -> 159.93333 | G17: =AVERAGE(G2:G16) -> 216.66667
B18: =MEDIAN(B2:B16) -> 12.48 | C18: =MEDIAN(C2:C16) -> 18.18 | D18: =MEDIAN(D2:D16) -> 147.84583 | E18: =MEDIAN(E2:E16) -> 60.740072 | F18: =MEDIAN(F2:F16) -> 92 | G18: =MEDIAN(G2:G16) -> 80

Sheet 企収
B1: 期間１０月２５日～６月１１日
B2: 企業名 | C2: 品種名 | D2: 収量（ｇ） | E2: 加工用（ｇ） | F2: パック数 | H2: 企業名 | I2: 品種名 | J2: 収量（ｇ） | K2: 加工用（ｇ） | L2: パック数 | N2: 企業名 | O2: 品種名 | P2: 収量（ｇ） | Q2: 加工用（ｇ） | R2: パック数 | T2: 企業名 | U2: 品種名 | V2: 収量（ｇ） | W2: 加工用（ｇ） | X2: パック数 | Z2: 企業名 | AA2: 品種名 | AB2: 収量（ｇ） | AC2: 加工用（ｇ） | AD2: パック数 | AF2: 企業名 | AG2: 品種名 | AH2: 収量（ｇ） | AI2: 加工用（ｇ） | AJ2: パック数 | AL2: 企業名 | AM2: 品種名 | AN2: 収量（ｇ） | AO2: 加工用（ｇ） | AP2: パック数 | AR2: 企業名 | AS2: 品種名 | AT2: 収量（ｇ） | AU2: 加工用（ｇ） | AV2: パック数 | AX2: 企業名 | AY2: 品種名 | AZ2: 収量（ｇ） | BA2: 加工用（ｇ） | BB2: パック数 | BD2: 企業名 | BE2: 品種名 | BF2: 収量（ｇ） | BG2: 加工用（ｇ） | BH2: パック数 | BJ2: 企業名 | BK2: 品種名 | BL2: 収量（ｇ） | BM2: 加工用（ｇ） | BN2: パック数 | BP2: 企業名 | BQ2: 品種名 | BR2: 収量（ｇ） | BS2: 加工用（ｇ） | BT2: パック数 | BV2: 企業名 | BW2: 品種名 | BX2: 収量（ｇ） | BY2: 加工用（ｇ） | BZ2: パック数 | CB2: 企業名 | CC2: 品種名 | CD2: 収量（ｇ） | CE2: 加工用（ｇ） | CF2: パック数 | CH2: 企業名 | CI2: 品種名 | CJ2: 収量（ｇ） | CK2: 加工用（ｇ） | CL2: パック数
B3: {=_xlfn._xlws.FILTER(元!D4:H447, 元!D4:D447="マルテー")} -> マルテー | C3: 紅ほっぺ（断） | D3: 100 | E3: 0 | F3: 0 | H3: {=_xlfn._xlws.FILTER(元!D4:H447, 元!D4:D447="三和")} -> 三和 | I3: 紅ほっぺ(断） | J3: 100 | K3: 0 | L3: 1 | N3: {=_xlfn._xlws.FILTER(元!D4:H447, 元!D4:D447="QB")} -> QB | O3: 紅ほっぺ（断） | P3: 195 | Q3: 0 | R3: 0 | T3: {=_xlfn._xlws.FILTER(元!D4:H447, 元!D4:D447="東レ")} -> 東レ | U3: 紅ほっぺ（断） | V3: 170 | W3: 0 | X3: 0 | Z3: {=_xlfn._xlws.FILTER(元!D4:H447, 元!D4:D447="Adobe")} -> Adobe | AA3: かおり野 | AB3: 240 | AC3: 0 | AD3: 3 | AF3: {=_xlfn._xlws.FILTER(元!D4:H447, 元!D4:D447="バリュ")} -> バリュ | AG3: 紅ほっぺ（断） | AH3: 400 | AI3: 0 | AJ3: 0 | AL3: {=_xlfn._xlws.FILTER(元!D4:H447, 元!D4:D447="ソリトン")} -> ソリトン | AM3: 紅ほっぺ | AN3: 100 | AO3: 0 | AP3: 0 | AR3: {=_xlfn._xlws.FILTER(元!D4:H447, 元!D4:D447="NaITO")} -> NaITO | AS3: 紅ほっぺ（断） | AT3: 60 | AU3: 0 | AV3: 0 | AX3: {=_xlfn._xlws.FILTER(元!D4:H447, 元!D4:D447="岡部")} -> 岡部 | AY3: 紅ほっぺ | AZ3: 500 | BA3: 0 | BB3: 3 | BD3: {=_xlfn._xlws.FILTER(元!D4:H447, 元!D4:D447="ケイアイ")} -> ケイアイ | BE3: 紅ほっぺ | BF3: 1500 | BG3: 0 | BH3: 13 | BJ3: {=_xlfn._xlws.FILTER(元!D4:H447, 元!D4:D447="富士機械")} -> 富士機械 | BK3: やよい姫 | BL3: 800 | BM3: 0 | BN3: 7 | BP3: {=_xlfn._xlws.FILTER(元!D4:H447, 元!D4:D447="慈誠会")} -> 慈誠会 | BQ3: 紅ほっぺ | BR3: 1080 | BS3: 740 | BT3: 9 | BV3: {=_xlfn._xlws.FILTER(元!D4:H447, 元!D4:D447="富士機材")} -> 富士機材 | BW3: やよい姫 | BX3: 440 | BY3: 1240 | BZ3: 3 | CB3: {=_xlfn._xlws.FILTER(元!D4:H447, ISNUMBER(SEARCH("昭和", 元!D4:D447)))} -> 昭和女子 | CC3: 紅ほっぺ | CD3: 80 | CE3: 0 | CF3: 0 | CH3: {=_xlfn._xlws.FILTER(元!D4:H447,ISNUMBER(SEARCH("日建",元!D4:D447)))} -> 日建 | CI3: 紅ほっぺ（断） | CJ3: 420 | CK3: 0 | CL3: 3
B4: マルテー | C4: 紅ほっぺ（断） | D4: 130 | E4: 0 | F4: 0 | H4: 三和 | I4: 紅ほっぺ（断） | J4: 46 | K4: 0 | L4: 0 | N4: QB | O4: 紅ほっぺ（断） | P4: 540 | Q4: 0 | R4: 3 | T4: 東レ | U4: よつぼし | V4: 0 | W4: 200 | X4: 0 | Z4: Adobe | AA4: かおり野 | AB4: 1510 | AC4: 0 | AD4: 12 | AF4: バリュ | AG4: 紅ほっぺ | AH4: 1140 | AI4: 0 | AJ4: 0 | AL4: ソリトン | AM4: 紅ほっぺ | AN4: 960 | AO4: 0 | AP4: 5 | AR4: NaITO | AS4: 紅ほっぺ（断） | AT4: 1480 | AU4: 0 | AV4: 13 | AX4: 岡部 | AY4: 紅ほっぺ | AZ4: 740 | BA4: 0 | BB4: 6 | BD4: ケイアイ | BE4: 紅ほっぺ | BF4: 2732 | BG4: 321 | BH4: 22 | BJ4: 富士機械 | BK4: やよいひめ | BL4: 1820 | BM4: 158 | BN4: 15 | BP4: 慈誠会 | BQ4: 紅ほっぺ | BR4: 600 | BS4: 90 | BT4: 5 | BV4: 富士機材 | BW4: やよいひめ | BX4: 260 | BY4: 110 | BZ4: 1 | CB4: 昭和女子 | CC4: 紅ほっぺ | CD4: 120 | CE4: 0 | CF4: 0 | CH4: 日建 | CI4: 紅ほっぺ（無） | CJ4: 840 | CK4: 80 | CL4: 5
B5: マルテー | C5: 紅ほっぺ（断） | D5: 100 | E5: 0 | F5: 0 | H5: 三和 | I5: 紅ほっぺ（断） | J5: 240 | K5: 0 | L5: 0 | N5: QB | O5: 紅ほっぺ（断） | P5: 80 | Q5: 0 | R5: 0 | T5: 東レ | U5: よつぼし | V5: 440 | W5: 0 | X5: 4 | Z5: Adobe | AA5: かおり野 | AB5: 3340 | AC5: 0 | AD5: 32 | AF5: バリュ | AG5: 紅ほっぺ | AH5: 1320 | AI5: 0 | AJ5: 11 | AL5: ソリトン | AM5: 紅ほっぺ | AN5: 980 | AO5: 0 | AP5: 8 | AR5: NaITO | AS5: 紅ほっぺ（無） | AT5: 950 | AU5: 130 | AV5: 8 | AX5: 岡部 | AY5: 紅ほっぺ | AZ5: 880 | BA5: 94 | BB5: 7 | BD5: ケイアイ | BE5: 紅ほっぺ | BF5: 2500 | BG5: 760 | BH5: 16 | BJ5: 富士機械 | BK5: やよいひめ | BL5: 1680 | BM5: 1540 | BN5: 12 | BP5: 慈誠会 | BQ5: 紅ほっぺ | BR5: 730 | BS5: 390 | BT5: 5 | BV5: 富士機材 | BW5: やよいひめ | BX5: 868 | BY5: 712 | BZ5: 7 | CB5: 昭和女子 | CC5: 紅ほっぺ | CD5: 340 | CE5: 0 | CF5: 0 | CH5: 日建 | CI5: 紅ほっぺ | CJ5: 1620 | CK5: 450 | CL5: 0
B6: マルテー | C6: 紅ほっぺ（断） | D6: 320 | E6: 0 | F6: 3 | H6: 三和 | I6: 紅ほっぺ（断） | J6: 380 | K6: 0 | L6: 2 | N6: QB | O6: 紅ほっぺ（断） | P6: 320 | Q6: 0 | R6: 0 | T6: 東レ | U6: よつぼし | V6: 960 | W6: 560 | X6: 8 | Z6: Adobe | AA6: かおり野 | AB6: 5140 | AC6: 0 | AD6: 31 | AF6: バリュ | AG6: 紅ほっぺ | AH6: 886 | AI6: 654 | AJ6: 8 | AL6: ソリトン | AM6: 紅ほっぺ | AN6: 880 | AO6: 208 | AP6: 7 | AR6: NaITO | AS6: 紅ほっぺ（無） | AT6: 810 | AU6: 660 | AV6: 6 | AX6: 岡部 | AY6: 紅ほっぺ | AZ6: 300 | BA6: 240 | BB6: 3 | BD6: ケイアイ | BE6: 紅ほっぺ | BF6: 1960 | BG6: 880 | BH6: 18 | BJ6: 富士機械 | BK6: やよいひめ | BL6: 1200 | BM6: 1640 | BN6: 11 | BP6: 慈誠会 | BQ6: 紅ほっぺ | BR6: 510 | BS6: 90 | BT6: 5 | BV6: 富士機材 | BW6: やよいひめ | BX6: 1370 | BY6: 1430 | BZ6: 11 | CB6: 昭和女子 | CC6: 紅ほっぺ | CD6: 600 | CE6: 0 | CF6: 5 | CH6: 日建 | CI6: 紅ほっぺ（無） | CJ6: 460 | CK6: 440 | CL6: 4
B7: マルテー | C7: 紅ほっぺ（断） | D7: 260 | E7: 0 | F7: 0 | H7: 三和 | I7: 0 | J7: 0 | K7: 0 | L7: 0 | N7: QB | O7: 紅ほっぺ（断） | P7: 100 | Q7: 0 | R7: 0 | T7: 東レ | U7: 紅ほっぺ | V7: 3940 | W7: 0 | X7: 28 | Z7: Adobe | AA7: かおり野 | AB7: 840 | AC7: 0 | AD7: 0 | AF7: バリュ | AG7: 紅ほっぺ | AH7: 1080 | AI7: 430 | AJ7: 5 | AL7: ソリトン | AM7: 紅ほっぺ | AN7: 1480 | AO7: 0 | AP7: 12 | AR7: NaITO | AS7: 紅ほっぺ（無） | AT7: 330 | AU7: 190 | AV7: 3 | AX7: 岡部 | AY7: 紅ほっぺ | AZ7: 320 | BA7: 180 | BB7: 3 | BD7: ケイアイ | BE7: 紅ほっぺ | BF7: 2440 | BG7: 340 | BH7: 16 | BJ7: 富士機械 | BK7: やよいひめ | BL7: 1060 | BM7: 2560 | BN7: 8 | BP7: 慈誠会 | BQ7: 紅ほっぺ | BR7: 110 | BS7: 250 | BT7: 1 | BV7: 富士機材 | BW7: やよいひめ | BX7: 1160 | BY7: 1600 | BZ7: 9 | CB7: 昭和 | CC7: 紅ほっぺ | CD7: 840 | CE7: 147 | CF7: 6 | CH7: 日建（遅） | CI7: 紅ほっぺ | CJ7: 740 | CK7: 300 | CL7: 4
B8: マルテー | C8: 紅ほっぺ（断） | D8: 320 | E8: 0 | F8: 0 | H8: 三和 | I8: 紅ほっぺ | J8: 0 | K8: 0 | L8: 0 | N8: QB | O8: 紅ほっぺ（断） | P8: 300 | Q8: 0 | R8: 1 | T8: 東レ | U8: よつぼし | V8: 160 | W8: 800 | X8: 0 | Z8: Adobe | AA8: かおり野 | AB8: 1600 | AC8: 500 | AD8: 15 | AF8: バリュ | AG8: 紅ほっぺ | AH8: 160 | AI8: 380 | AJ8: 1 | AL8: ソリトン | AM8: 紅ほっぺ | AN8: 780 | AO8: 260 | AP8: 7 | AR8: NaITO | AS8: 紅ほっぺ（無） | AT8: 850 | AU8: 230 | AV8: 4 | AX8: 岡部 | AY8: 紅ほっぺ | AZ8: 140 | BA8: 300 | BB8: 1 | BD8: ケイアイ | BE8: 紅ほっぺ | BF8: 1340 | BG8: 740 | BH8: 10 | BJ8: 富士機械 | BK8: やよいひめ | BL8: 600 | BM8: 1760 | BN8: 5 | BP8: 慈誠会 | BQ8: 紅ほっぺ | BR8: 100 | BS8: 320 | BT8: 1 | BV8: 富士機材 | BW8: やよいひめ | BX8: 0 | BY8: 0 | BZ8: 0 | CB8: 昭和 | CC8: 紅ほっぺ | CD8: 820 | CE8: 747 | CF8: 8 | CH8: 日建 | CI8: 紅ほっぺ（無） | CJ8: 0 | CK8: 0 | CL8: 0
B9: マルテー | C9: よつぼし | D9: 46 | E9: 0 | F9: 0 | H9: 三和 | I9: 紅ほっぺ | J9: 500 | K9: 320 | L9: 0 | N9: QB | O9: 紅ほっぺ（無） | P9: 380 | Q9: 180 | R9: 3 | T9: 東レ | U9: よつぼし | V9: 1240 | W9: 0 | X9: 10 | Z9: Adobe | AA9: かおり野 | AB9: 4700 | AC9: 0 | AD9: 42 | AF9: バリュ | AG9: 紅ほっぺ | AH9: 220 | AI9: 180 | AJ9: 2 | AL9: ソリトン | AM9: 紅ほっぺ | AN9: 520 | AO9: 120 | AP9: 5 | AR9: NaITO | AS9: 紅ほっぺ（無） | AT9: 210 | AU9: 390 | AV9: 1 | AX9: 岡部 | AY9: 紅ほっぺ | AZ9: 240 | BA9: 0 | BB9: 0 | BD9: ケイアイ | BE9: 紅ほっぺ | BF9: 430 | BG9: 830 | BH9: 0 | BJ9: 富士機械 | BK9: やよいひめ | BL9: 250 | BM9: 1510 | BN9: 2 | BP9: 慈誠会 | BQ9: 紅ほっぺ | BR9: 30 | BS9: 260 | BT9: 0 | BV9: 富士機材 | BW9: やよいひめ | BX9: 1340 | BY9: 2060 | BZ9: 7 | CB9: 昭和 | CC9: 紅ほっぺ | CD9: 114 | CE9: 366 | CF9: 1 | CH9: 日建（遅） | CI9: 紅ほっぺ | CJ9: 0 | CK9: 0 | CL9: 0
B10: マルテー | C10: 紅ほっぺ（断） | D10: 200 | E10: 0 | F10: 0 | H10: 三和 | I10: 紅ほっぺ | J10: 0 | K10: 0 | L10: 0 | N10: QB | O10: 紅ほっぺ（無） | P10: 480 | Q10: 100 | R10: 3 | T10: 東レ | U10: 紅ほっぺ | V10: 820 | W10: 0 | X10: 7 | Z10: Adobe | AA10: かおり野 | AB10: 1460 | AC10: 0 | AD10: 12 | AF10: バリュ | AG10: 紅ほっぺ | AH10: 170 | AI10: 135 | AJ10: 1 | AL10: ソリトン | AM10: 紅ほっぺ | AN10: 600 | AO10: 439 | AP10: 4 | AR10: NaITO | AS10: 紅ほっぺ（無） | AT10: 45 | AU10: 426 | AV10: 1 | AX10: 岡部 | AY10: 紅ほっぺ | AZ10: 0 | BA10: 360 | BB10: 0 | BD10: ケイアイ | BE10: 紅ほっぺ | BF10: 0 | BG10: 0 | BH10: 0 | BJ10: 富士機械 | BK10: 弥生姫 | BL10: 50 | BM10: 1320 | BN10: 0 | BP10: 慈誠会 | BQ10: 紅ほっぺ | BR10: 0 | BS10: 40 | BT10: 0 | BV10: 富士機材 | BW10: 弥生姫 | BX10: 460 | BY10: 1620 | BZ10: 3 | CB10: 昭和 | CC10: 紅ほっぺ | CD10: 550 | CE10: 230 | CF10: 5 | CH10: 日建 | CI10: 紅ほっぺ（無） | CJ10: 240 | CK10: 720 | CL10: 2
B11: マルテー | C11: かおり野 | D11: 120 | E11: 0 | F11: 0 | H11: 三和 | I11: 紅ほっぺ | J11: 260 | K11: 530 | L11: 1 | N11: QB | O11: 紅ほっぺ（無） | P11: 420 | Q11: 260 | R11: 4 | T11: 東レ | U11: よつぼし | V11: 1880 | W11: 2480 | X11: 10 | Z11: Adobe | AA11: かおり野 | AB11: 820 | AC11: 822 | AD11: 8 | AF11: バリュ | AG11: 紅ほっぺ | AH11: 0 | AI11: 0 | AJ11: 0 | AL11: ソリトン | AM11: 紅ほっぺ | AN11: 740 | AO11: 500 | AP11: 7 | AR11: NaITO | AS11: 紅ほっぺ（無） | AT11: 0 | AU11: 843 | AV11: 0 | AX11: 岡部 | AY11: 紅ほっぺ | AZ11: 0 | BA11: 630 | BB11: 0 | BD11: ケイアイ | BE11: 紅ほっぺ | BF11: 0 | BG11: 40 | BH11: 0 | BJ11: 富士機械 | BK11: やよいひめ | BL11: 130 | BM11: 1550 | BN11: 1 | BP11: 慈誠会 | BQ11: 紅ほっぺ | BR11: 0 | BS11: 80 | BT11: 0 | BV11: 富士機材 | BW11: やよいひめ | BX11: 460 | BY11: 1800 | BZ11: 2 | CB11: 昭和 | CC11: 紅ほっぺ | CD11: 340 | CE11: 320 | CF11: 3 | CH11: 日建（遅） | CI11: 紅ほっぺ | CJ11: 0 | CK11: 119 | CL11: 22
B12: マルテー | C12: かおり野 | D12: 240 | E12: 0 | F12: 0 | H12: 三和 | I12: 紅ほっぺ | J12: 0 | K12: 0 | L12: 0 | N12: QB | O12: 紅ほっぺ（無） | P12: 495 | Q12: 125 | R12: 3 | T12: 東レ | U12: 紅ほっぺ（無） | V12: 1240 | W12: 420 | X12: 8 | Z12: Adobe | AA12: かおり野 | AB12: 1880 | AC12: 665 | AD12: 9 | AF12: バリュ | AG12: 紅ほっぺ | AH12: 0 | AI12: 0 | AJ12: 0 | AL12: ソリトン | AM12: 紅ほっぺ | AN12: 480 | AO12: 620 | AP12: 4 | AR12: NaITO | AS12: 無 | AT12: 0 | AU12: 634 | AV12: 0 | AX12: 岡部 | AY12: 紅ほっぺ | AZ12: 0 | BA12: 30 | BB12: 0 | BD12: ケイアイ | BE12: 紅ほっぺ | BF12: 340 | BG12: 320 | BH12: 3 | BJ12: 富士機械 | BK12: やよいひめ | BL12: 0 | BM12: 600 | BN12: 0 | BP12: 慈誠会 | BQ12: 紅ほっぺ | BR12: 100 | BS12: 40 | BT12: 1 | BV12: 富士機材 | BW12: やよいひめ | BX12: 860 | BY12: 1740 | BZ12: 7 | CB12: 昭和 | CC12: 紅ほっぺ | CD12: 300 | CE12: 180 | CF12: 2 | CH12: 日建 | CI12: 紅ほっぺ（無） | CJ12: 280 | CK12: 160 | CL12: 1
B13: マルテー | C13: よつぼし | D13: 240 | E13: 0 | F13: 0 | H13: 三和 | I13: 紅ほっぺ | J13: 0 | K13: 660 | L13: 0 | N13: QB | O13: 紅ほっぺ（無） | P13: 140 | Q13: 200 | R13: 1 | T13: 東レ | U13: よつぼし | V13: 2036 | W13: 435 | X13: 15 | Z13: Adobe | AA13: かおり野 | AB13: 400 | AC13: 920 | AD13: 4 | AF13: バリュ | AG13: 紅ほっぺ | AH13: 466 | AI13: 1474 | AJ13: 3 | AL13: ソリトン | AM13: 紅ほっぺ | AN13: 180 | AO13: 80 | AP13: 1 | AR13: NaITO | AS13: 無 | AT13: 0 | AU13: 120 | AV13: 0 | AX13: 岡部 | AY13: 紅ほっぺ | AZ13: 400 | BA13: 500 | BB13: 4 | BD13: ケイアイ | BE13: 紅ほっぺ | BF13: 320 | BG13: 540 | BH13: 15 | BJ13: 富士機械 | BK13: やよいひめ | BL13: 240 | BM13: 1360 | BN13: 2 | BP13: 慈誠会 | BQ13: 紅ほっぺ | BR13: 180 | BS13: 100 | BT13: 2 | BV13: 富士機材 | BW13: やよいひめ | BX13: 590 | BY13: 570 | BZ13: 4 | CB13: 昭和 | CC13: 紅ほっぺ | CD13: 540 | CE13: 480 | CF13: 3 | CH13: 日建（遅） | CI13: 紅ほっぺ | CJ13: 0 | CK13: 0 | CL13: 0
B14: マルテー | C14: 紅ほっぺ（断） | D14: 260 | E14: 0 | F14: 0 | H14: 三和 | I14: 紅ほっぺ | J14: 450 | K14: 350 | L14: 4 | N14: QB | O14: 紅ほっぺ（無） | P14: 167 | Q14: 366 | R14: 1 | T14: 東レ | U14: 紅ほっぺ（無） | V14: 1800 | W14: 0 | X14: 8 | Z14: Adobe | AA14: かおり野 | AB14: 580 | AC14: 180 | AD14: 5 | AF14: バリュ | AG14: 無 | AH14: 400 | AI14: 1240 | AJ14: 3 | AL14: ソリトン | AM14: 紅ほっぺ | AN14: 0 | AO14: 260 | AP14: 0 | AR14: NaITO | AS14: 無 | AT14: 20 | AU14: 170 | AV14: 0 | AX14: 岡部 | AY14: 紅ほっぺ | AZ14: 160 | BA14: 260 | BB14: 1 | BD14: ケイアイ | BE14: 紅ほっぺ | BF14: 1210 | BG14: 340 | BH14: 12 | BJ14: 富士機械 | BK14: やよいひめ | BL14: 1010 | BM14: 2020 | BN14: 9 | BP14: 慈誠会 | BQ14: 紅ほっぺ | BR14: 240 | BS14: 280 | BT14: 2 | BV14: 富士機材 | BW14: やよいひめ | BX14: 500 | BY14: 220 | BZ14: 5 | CB14: 昭和 | CC14: 紅ほっぺ | CD14: 76 | CE14: 104 | CF14: 0 | CH14: 日建 | CI14: 紅ほっぺ（無） | CJ14: 0 | CK14: 0 | CL14: 0
B15: マルテー | C15: 紅ほっぺ（断） | D15: 120 | E15: 0 | F15: 0 | H15: 三和 | I15: 紅ほっぺ | J15: 0 | K15: 520 | L15: 0 | N15: QB | O15: 紅ほっぺ（無） | P15: 0 | Q15: 550 | R15: 0 | T15: 東レ | U15: よつぼし | V15: 1990 | W15: 1250 | X15: 17 | Z15: Adobe | AA15: かおり野 | AB15: 1500 | AC15: 573 | AD15: 5 | AF15: バリュ | AG15: 無 | AH15: 270 | AI15: 510 | AJ15: 2 | AL15: ソリトン | AM15: 紅ほっぺ | AN15: 110 | AO15: 170 | AP15: 1 | AR15: NaITO | AS15: 無 | AT15: 130 | AU15: 170 | AV15: 1 | AX15: 岡部 | AY15: 紅ほっぺ | AZ15: 120 | BA15: 0 | BB15: 1 | BD15: ケイアイ | BE15: 紅ほっぺ | BF15: 610 | BG15: 90 | BH15: 6 | BJ15: 富士機械 | BK15: やよいひめ | BL15: 2270 | BM15: 1650 | BN15: 21 | BP15: 慈誠会 | BQ15: 紅ほっぺ | BR15: 140 | BS15: 140 | BT15: 1 | BV15: 富士機材 | BW15: やよいひめ | BX15: 2890 | BY15: 290 | BZ15: 22 | CB15: 昭和 | CC15: 紅ほっぺ | CD15: 0 | CE15: 240 | CF15: 0 | CH15: 日建（遅） | CI15: 紅ほっぺ | CJ15: 0 | CK15: 0 | CL15: 0
B16: マルテー | C16: よつぼし | D16: 220 | E16: 0 | F16: 0 | H16: 三和 | I16: 紅ほっぺ | J16: 140 | K16: 520 | L16: 1 | N16: QB | O16: 無 | P16: 0 | Q16: 180 | R16: 0 | T16: 東レ | U16: 紅ほっぺ（無） | V16: 2300 | W16: 2707 | X16: 23 | Z16: Adobe | AA16: かおり野 | AB16: 300 | AC16: 940 | AD16: 2 | AF16: バリュ | AG16: やよいひめ | AH16: 340 | AI16: 750 | AJ16: 3 | AL16: ソリトン | AM16: 紅ほっぺ | AN16: 310 | AO16: 190 | AP16: 4 | AR16: NaITO | AS16: 無 | AT16: 450 | AU16: 260 | AV16: 4 | AX16: 岡部 | AY16: 紅ほっぺ | AZ16: 0 | BA16: 120 | BB16: 0 | BD16: ケイアイ | BE16: 紅ほっぺ | BF16: 790 | BG16: 250 | BH16: 8 | BJ16: 富士機械 | BK16: やよいひめ | BL16: 5510 | BM16: 1250 | BN16: 52 | BP16: 慈誠会 | BQ16: 紅ほっぺ | BR16: 300 | BS16: 80 | BT16: 3 | BV16: 富士機材 | BW16: やよいひめ | BX16: 2510 | BY16: 10 | BZ16: 18 | CB16: 昭和 | CC16: 紅ほっぺ | CD16: 0 | CE16: 120 | CF16: 0 | CH16: 日建 | CI16: 紅ほっぺ（無） | CJ16: 0 | CK16: 0 | CL16: 0
B17: マルテー | C17: かおり野 | D17: 480 | E17: 0 | F17: 0 | H17: 三和 | I17: 紅ほっぺ | J17: 500 | K17: 0 | L17: 0 | N17: QB | O17: 無 | P17: 0 | Q17: 165 | R17: 0 | T17: 東レ | U17: よつぼし | V17: 1990 | W17: 1350 | X17: 17 | Z17: Adobe | AA17: かおり野 | AB17: 0 | AC17: 0 | AD17: 0 | AF17: バリュ | AG17: 無 | AH17: 230 | AI17: 620 | AJ17: 2 | AL17: ソリトン | AM17: 紅ほっぺ | AN17: 780 | AO17: 360 | AP17: 5 | AR17: NaITO | AS17: 無 | AT17: 590 | AU17: 260 | AV17: 5 | AX17: 岡部 | AY17: 紅ほっぺ | AZ17: 230 | BA17: 470 | BB17: 2 | BD17: ケイアイ | BE17: 紅ほっぺ | BF17: 1230 | BG17: 230 | BH17: 12 | BJ17: 富士機械 | BK17: やよいひめ | BL17: 2530 | BM17: 810 | BN17: 23 | BP17: 慈誠会 | BQ17: 紅ほっぺ | BR17: 420 | BS17: 80 | BT17: 4 | BV17: 富士機材 | BW17: やよいひめ | BX17: 1530 | BY17: 30 | BZ17: 15 | CB17: 昭和 | CC17: 紅ほっぺ | CD17: 0 | CE17: 260 | CF17: 0 | CH17: 日建（遅） | CI17: 紅ほっぺ | CJ17: 0 | CK17: 0 | CL17: 0
B18: マルテー | C18: 紅ほっぺ（断） | D18: 120 | E18: 0 | F18: 0 | N18: QB | O18: 無 | P18: 200 | Q18: 0 | R18: 2 | T18: 東レ | U18: 紅ほっぺ（無） | V18: 1240 | W18: 1532 | X18: 9 | Z18: Adobe | AA18: かおり野 | AB18: 140 | AC18: 600 | AD18: 1 | AF18: バリュ | AG18: やよいひめ | AH18: 330 | AI18: 290 | AJ18: 3 | AL18: ソリトン | AM18: 紅ほっぺ | AN18: 420 | AO18: 200 | AP18: 4 | AR18: NaITO | AS18: 無 | AT18: 500 | AU18: 170 | AV18: 5 | AX18: 岡部 | AY18: 紅ほっぺ | AZ18: 100 | BA18: 340 | BB18: 1 | BD18: ケイアイ | BE18: 紅ほっぺ | BF18: 2100 | BG18: 480 | BH18: 19 | BJ18: 富士機械 | BK18: やよいひめ | BL18: 910 | BM18: 70 | BN18: 7 | BP18: 慈誠会 | BQ18: 紅ほっぺ | BR18: 350 | BS18: 270 | BT18: 2 | BV18: 富士機材 | BW18: やよいひめ | BX18: 600 | BY18: 0 | BZ18: 4 | CB18: 昭和 | CC18: 紅ほっぺ | CD18: 80 | CE18: 240 | CF18: 0 | CH18: 日建 | CI18: 無 | CJ18: 0 | CK18: 240 | CL18: 0
B19: マルテー | C19: かおり野 | D19: 300 | E19: 0 | F19: 0 | N19: QB | O19: 無 | P19: 100 | Q19: 60 | R19: 1 | T19: 東レ | U19: よつぼし | V19: 2300 | W19: 325 | X19: 22 | Z19: Adobe | AA19: かおり野 | AB19: 1660 | AC19: 830 | AD19: 13 | AF19: バリュ | AG19: 無 | AH19: 460 | AI19: 240 | AJ19: 2 | AL19: ソリトン | AM19: 紅ほっぺ | AN19: 470 | AO19: 210 | AP19: 4 | AR19: NaITO | AS19: 無 | AT19: 210 | AU19: 30 | AV19: 2 | AX19: 岡部 | AY19: 紅ほっぺ | AZ19: 500 | BA19: 0 | BB19: 15 | BD19: ケイアイ | BE19: 紅ほっぺ | BF19: 1500 | BG19: 1120 | BH19: 14 | BJ19: 富士機械 | BK19: やよいひめ | BL19: 3100 | BM19: 510 | BN19: 31 | BP19: 慈誠会 | BQ19: 紅ほっぺ | BR19: 260 | BS19: 600 | BT19: 2 | BV19: 富士機材 | BW19: やよいひめ | BX19: 1020 | BY19: 0 | BZ19: 7 | CB19: 昭和 | CC19: 紅ほっぺ | CD19: 0 | CE19: 320 | CF19: 0
B20: マルテー | C20: よつぼし | D20: 500 | E20: 0 | F20: 0 | N20: QB | O20: 無 | P20: 0 | Q20: 150 | R20: 0 | T20: 東レ | U20: 紅ほっぺ（無） | V20: 1020 | W20: 1280 | X20: 7 | Z20: Adobe | AA20: かおり野 | AB20: 2800 | AC20: 1060 | AD20: 24 | AF20: バリュ | AG20: やよいひめ | AH20: 320 | AI20: 280 | AJ20: 2 | AL20: ソリトン | AM20: 紅ほっぺ | AN20: 750 | AO20: 450 | AP20: 7 | AR20: NaITO | AS20: 無 | AT20: 470 | AU20: 880 | AV20: 3 | BD20: ケイアイ | BE20: 紅ほっぺ | BF20: 1060 | BG20: 740 | BH20: 10 | BJ20: 富士機械 | BK20: やよいひめ | BL20: 1760 | BM20: 620 | BN20: 15 | BP20: 慈誠会 | BQ20: 紅ほっぺ | BR20: 120 | BS20: 500 | BT20: 1 | BV20: 富士機材 | BW20: やよいひめ | BX20: 2960 | BY20: 360 | BZ20: 26 | CB20: 昭和 | CC20: 紅ほっぺ | CD20: 90 | CE20: 170 | CF20: 0
B21: マルテー | C21: 紅ほっぺ（断） | D21: 1120 | E21: 0 | F21: 10 | N21: QB | O21: 無 | P21: 360 | Q21: 200 | R21: 2 | T21: 東レ | U21: よつぼし | V21: 1326 | W21: 2050 | X21: 12 | Z21: Adobe | AA21: かおり野 | AB21: 3640 | AC21: 1120 | AD21: 26 | AF21: バリュ | AG21: 紅ほっぺ | AH21: 100 | AI21: 160 | AJ21: 1 | AL21: ソリトン | AM21: 紅ほっぺ | AN21: 370 | AO21: 570 | AP21: 3 | AR21: NaITO | AS21: 無 | AT21: 900 | AU21: 870 | AV21: 7 | BD21: ケイアイ | BE21: 紅ほっぺ | BF21: 830 | BG21: 470 | BH21: 4 | BJ21: 富士機械 | BK21: やよいひめ | BL21: 220 | BM21: 1120 | BN21: 2 | BP21: 慈誠会 | BQ21: 紅ほっぺ | BR21: 1140 | BS21: 0 | BT21: 0 | BV21: 富士機材 | BW21: やよいひめ | BX21: 1010 | BY21: 450 | BZ21: 7 | CB21: 昭和 | CC21: 紅ほっぺ | CD21: 120 | CE21: 160 | CF21: 1
B22: マルテー | C22: よつぼし | D22: 880 | E22: 0 | F22: 6 | N22: QB | O22: 無 | P22: 150 | Q22: 0 | R22: 1 | T22: 東レ | U22: 紅ほっぺ（無） | V22: 280 | W22: 1610 | X22: 0 | Z22: Adobe | AA22: かおりの | AB22: 2330 | AC22: 1170 | AD22: 25 | AF22: バリュ | AG22: 無 | AH22: 590 | AI22: 430 | AJ22: 4 | AL22: ソリトン | AM22: 紅ほっぺ | AN22: 240 | AO22: 760 | AP22: 2 | AR22: NaITO | AS22: 無 | AT22: 920 | AU22: 840 | AV22: 1 | BD22: ケイアイ | BE22: 紅ほっぺ | BF22: 900 | BG22: 600 | BH22: 0 | BJ22: 富士機械 | BK22: やよいひめ | BL22: 110 | BM22: 330 | BN22: 1 | BP22: 慈誠会 | BQ22: 紅ほっぺ | BR22: 320 | BS22: 0 | BT22: 4 | BV22: 富士機材 | BW22: やよいひめ | BX22: 1900 | BY22: 2800 | BZ22: 13 | CB22: 昭和 | CC22: 紅ほっぺ | CD22: 450 | CE22: 290 | CF22: 4
B23: マルテー | C23: かおり野 | D23: 220 | E23: 0 | F23: 1 | N23: QB | O23: 無 | P23: 100 | Q23: 0 | R23: 0 | T23: 東レ | U23: よつぼし | V23: 1160 | W23: 2420 | X23: 11 | Z23: Adobe | AA23: かおりの | AB23: 2180 | AC23: 1000 | AD23: 17 | AF23: バリュ | AG23: やよいひめ | AH23: 190 | AI23: 150 | AJ23: 1 | AL23: ソリトン | AM23: 紅ほっぺ | AN23: 210 | AO23: 310 | AP23: 2 | AR23: NaITO | AS23: 無 | AT23: 200 | AU23: 420 | AV23: 2 | BD23: ケイアイ | BE23: 紅ほっぺ | BF23: 1400 | BG23: 0 | BH23: 0 | BV23: 富士機材 | BW23: やよいひめ | BX23: 3800 | BY23: 0 | BZ23: 8 | CB23: 昭和 | CC23: 紅ほっぺ | CD23: 170 | CE23: 330 | CF23: 2
B24: マルテー | C24: 紅ほっぺ（断） | D24: 2300 | E24: 0 | F24: 21 | T24: 東レ | U24: 紅ほっぺ（無） | V24: 1600 | W24: 1100 | X24: 5 | Z24: Adobe | AA24: かおりの | AB24: 2700 | AC24: 2260 | AD24: 22 | AF24: バリュ | AG24: 無 | AH24: 1150 | AI24: 520 | AJ24: 10 | AL24: ソリトン | AM24: 紅ほっぺ | AN24: 1120 | AO24: 0 | AP24: 0 | AR24: NaITO | AS24: 無 | AT24: 170 | AU24: 150 | AV24: 0 | BD24: ケイアイ | BE24: 紅ほっぺ | BF24: 1200 | BG24: 0 | BH24: 0 | CB24: 昭和 | CC24: 紅ほっぺ | CD24: 260 | CE24: 660 | CF24: 2
B25: マルテー | C25: よつぼし | D25: 500 | E25: 0 | F25: 2 | T25: 東レ | U25: よつぼし | V25: 551 | W25: 479 | X25: 5 | Z25: Adobe | AA25: かおり野 | AB25: 1280 | AC25: 4980 | AD25: 11 | AF25: バリュ | AG25: やよいひめ | AH25: 510 | AI25: 390 | AJ25: 3 | AR25: Naito | AS25: 無 | AT25: 300 | AU25: 0 | AV25: 0 | CB25: 昭和 | CC25: 紅ほっぺ | CD25: 40 | CE25: 350 | CF25: 0
B26: マルテー | C26: かおり野 | D26: 520 | E26: 0 | F26: 2 | T26: 東レ | U26: 無 | V26: 0 | W26: 630 | X26: 0 | Z26: Adobe | AA26: かおりの | AB26: 180 | AC26: 830 | AD26: 1 | AF26: バリュ | AG26: 無 | AH26: 1730 | AI26: 700 | AJ26: 16 | CB26: 昭和 | CC26: 紅ほっぺ | CD26: 300 | CE26: 0 | CF26: 0
B27: マルテー | C27: やよい姫 | D27: 300 | E27: 0 | F27: 1 | T27: 東レ | U27: よつぼし | V27: 440 | W27: 1360 | X27: 4 | Z27: Adobe | AA27: かおりの | AB27: 200 | AC27: 480 | AD27: 2 | AF27: バリュ | AG27: やよいひめ | AH27: 780 | AI27: 1250 | AJ27: 4
B28: マルテー | C28: 紅ほっぺ（無） | D28: 1840 | E28: 0 | F28: 17 | T28: 東レ | U28: よつぼし | V28: 100 | W28: 610 | X28: 1 | Z28: Adobe | AA28: かおりの | AB28: 740 | AC28: 0 | AD28: 1 | AF28: バリュ | AG28: 無 | AH28: 880 | AI28: 670 | AJ28: 8
B29: マルテー | C29: かおり野 | D29: 128 | E29: 282 | F29: 1 | T29: 東レ | U29: よつぼし | V29: 100 | W29: 0 | X29: 1 | AF29: バリュ | AG29: やよいひめ | AH29: 460 | AI29: 0 | AJ29: 2
B30: マルテー | C30: よつぼし | D30: 210 | E30: 330 | F30: 2 | T30: 東レ | U30: 無 | V30: 240 | W30: 330 | X30: 2 | AF30: バリュ | AG30: 無 | AH30: 450 | AI30: 140 | AJ30: 4
B31: マルテー | C31: やよい姫 | D31: 220 | E31: 300 | F31: 2 | T31: 東レ | U31: よつぼし | V31: 1840 | W31: 230 | X31: 17 | AF31: バリュ | AG31: やよいひめ | AH31: 200 | AI31: 120 | AJ31: 2
B32: マルテー | C32: 紅ほっぺ（無） | D32: 2840 | E32: 1020 | F32: 26 | T32: 東レ | U32: よつぼし | V32: 2250 | W32: 240 | X32: 21 | AF32: バリュ | AG32: 無 | AH32: 4000 | AI32: 1560 | AJ32: 38
B33: マルテー | C33: 紅ほっぺ（無） | D33: 2740 | E33: 470 | F33: 22 | T33: 東レ | U33: 無 | V33: 1600 | W33: 860 | X33: 15 | AF33: バリュ | AG33: やよいひめ | AH33: 4170 | AI33: 1400 | AJ33: 40
B34: マルテー | C34: 紅ほっぺ（無） | D34: 2160 | E34: 500 | F34: 15 | T34: 東レ | U34: よつぼし | V34: 5420 | W34: 500 | X34: 39 | AF34: バリュ | AG34: やよいひめ | AH34: 680 | AI34: 0 | AJ34: 5
B35: マルテー | C35: かおり野 | D35: 300 | E35: 90 | F35: 2 | T35: 東レ | U35: 無 | V35: 3060 | W35: 1580 | X35: 22 | AF35: バリュ | AG35: 無 | AH35: 840 | AI35: 300 | AJ35: 6
B36: マルテー | C36: よつぼし | D36: 220 | E36: 120 | F36: 1 | T36: 東レ | U36: よつぼし | V36: 4290 | W36: 3330 | X36: 40 | AF36: バリュ | AG36: やよいひめ | AH36: 370 | AI36: 130 | AJ36: 3
B37: マルテー | C37: やよいひめ | D37: 180 | E37: 60 | F37: 1 | T37: 東レ | U37: 無 | V37: 3000 | W37: 2000 | X37: 28 | AF37: バリュ | AG37: 無 | AH37: 410 | AI37: 880 | AJ37: 2
B38: マルテー | C38: 紅ほっぺ（無） | D38: 1468 | E38: 332 | F38: 12 | T38: 東レ | U38: よつぼし | V38: 1110 | W38: 2930 | X38: 11 | AF38: バリュ | AG38: やよいひめ | AH38: 850 | AI38: 0 | AJ38: 6
B39: マルテー | C39: 紅ほっぺ（無） | D39: 3480 | E39: 460 | F39: 32 | T39: 東レ | U39: 無 | V39: 2120 | W39: 6920 | X39: 19 | AF39: バリュ | AG39: 無 | AH39: 240 | AI39: 0 | AJ39: 2
B40: マルテー | C40: かおり野 | D40: 260 | E40: 40 | F40: 2 | T40: 東レ | U40: よつぼし | V40: 0 | W40: 3400 | X40: 0 | AF40: バリュ | AG40: やよいひめ | AH40: 480 | AI40: 0 | AJ40: 4
...

Sheet 品
B1: 期間１０月２５日～６月１１日
B2: 品種名 | C2: 正規品（ｇ） | D2: 加工用（ｇ） | E2: パック数 | F2: 収穫量（ｇ） | G2: 株数 | H2: 面積（㎡） | I2: 1株あたり収量（ｇ） | J2: 歩留まり（％） | K2: 加工比率（％） | L2: 10aあたり収量(kg) | N2: いちごの1株あたり収量の目安
B3: かおり野 | C3: =SUM(企収!AB3:AB28) -> 42160 | D3: =SUM(企収!AC3:AC28) -> 18930 | E3: =SUM(企収!AD3:AD28) -> 323 | F3: =SUM(C3:D3) -> 61090 | G3: 360 | H3: 16.8 | I3: =F3/G3 -> 169.69444 | J3: =(C3/F3)*100 -> 69.012932 | K3: =(D3/F3)*100 -> 30.987068 | L3: =F3 / H3* 100 / 1000 -> 363.63095
B4: よつぼし | C4: =SUM(品収!G3:G54) -> 45149 | D4: =SUM(品収!H3:H54) -> 40735 | E4: =SUM(品収!I3:I54) -> 306 | F4: =SUM(C4:D4) -> 85884 | G4: 360 | H4: 17 | I4: =F4/G4 -> 238.56667 | J4: =(C4/F4)*100 -> 52.569745 | K4: =(D4/F4)*100 -> 47.430255 | L4: =F4 / H4* 100 / 1000 -> 505.2 | N4: 栽培方法 | O4: 目安（1株あたり収量）
B5: やよいひめ | C5: =SUM(品収!L3:L75) -> 65668 | D5: =SUM(品収!M3:M75) -> 46370 | E5: =SUM(品収!N3:N75) -> 510 | F5: =SUM(C5:D5) -> 112038 | G5: 700 | H5: 34 | I5: =F5/G5 -> 160.05429 | J5: =(C5/F5)*100 -> 58.612257 | K5: =(D5/F5)*100 -> 41.387743 | L5: =F5 / H5* 100 / 1000 -> 329.52353 | N5: 高設砂栽培 | O5: 250～350g/株
B6: 紅ほっぺ | C6: =SUM(品収!Q3:Q265) -> 181146 | D6: =SUM(品収!R3:R265) -> 111519 | E6: =SUM(品収!S3:S265) -> 1231 | F6: =SUM(C6:D6) -> 292665 | G6: =G7-(G3+G4+G5) -> 1830 | H6: =202-H3-H4-H5 -> 134.2 | I6: =F6/G6 -> 159.92623 | J6: =(C6/F6)*100 -> 61.895341 | K6: =(D6/F6)*100 -> 38.104659 | L6: =F6 / H6* 100 / 1000 -> 218.08122 | N6: 土耕栽培 | O6: 150～250g/株
B7: 合計 | C7: =SUM(C3:C6) -> 334123 | D7: =SUM(D3:D6) -> 217554 | E7: =SUM(E3:E6) -> 2370 | F7: =SUM(F3:F6) -> 551677 | G7: 3250 | H7: =SUM(H3:H6) -> 202 | N7: 備考
B8: 平均 | C8: =AVERAGE(C3:C6) -> 83530.75 | D8: =AVERAGE(D3:D6) -> 54388.5 | E8: =AVERAGE(E3:E6) -> 592.5 | F8: =AVERAGE(F3:F6) -> 137919.25 | G8: =AVERAGE(G3:G6) -> 812.5 | H8: =AVERAGE(H3:H6) -> 50.5 | I8: =AVERAGE(I3:I6) -> 182.06041 | J8: =AVERAGE(J3:J6) -> 60.522569 | ... L8: =AVERAGE(L3:L6) -> 354.10893 | N8: 管理が行き届けば400g以上も可能
B9: 中央値 | C9: =MEDIAN(C3:C6) -> 55408.5 | D9: =MEDIAN(D3:D6) -> 43552.5 | E9: =MEDIAN(E3:E6) -> 416.5 | F9: =MEDIAN(F3:F6) -> 98961 | G9: =MEDIAN(G3:G6) -> 530 | H9: =MEDIAN(H3:H6) -> 25.5 | I9: =MEDIAN(I3:I6) -> 164.87437 | J9: =MEDIAN(J3:J6) -> 60.253799 | ... L9: =MEDIAN(L3:L6) -> 346.57724 | N9: 路地では150g前後になることも多い
A10: 偏差 | B10: かおり野 | C10: =C3-83530 -> -41370 | D10: =D3-54338 -> -35408 | E10: =E3-592 -> -269 | F10: =F3-551677 -> -490587
B11: よつぼし | C11: =C4-83530 -> -38381 | D11: =D4-54338 -> -13603 | E11: =E4-592 -> -286 | F11: =F4-551677 -> -465793
B12: やよいひめ | C12: =C5-83530 -> -17862 | D12: =D5-54338 -> -7968 | E12: =E5-592 -> -82 | F12: =F5-551677 -> -439639
B13: 紅ほっぺ | C13: =C6-83530 -> 97616 | D13: =D6-54338 -> 57181 | E13: =E6-592 -> 639 | F13: =F6-551677 -> -259012
B14: 分散 | C14: {=SUM(C10:C13*C10:C13)/COUNT(C10:C13)} -> 3.2581281e+09 | D14: {=SUM(D10:D13*D10:D13)/COUNT(D10:D13)} -> 1.192981e+09 | E14: {=SUM(E10:E13*E10:E13)/COUNT(E10:E13)} -> 142300.5 | F14: {=SUM(F10:F13*F10:F13)/COUNT(F10:F13)} -> 1.795021e+11
B15: 標準偏差 | C15: =SQRT(C14) -> 57080.015 | D15: =SQRT(D14) -> 34539.557 | E15: =SQRT(E14) -> 377.22739 | F15: =SQRT(F14) -> 423676.88
B21: 品種名 | C21: 正規品（kｇ） | D21: 加工用（kｇ） | E21: パック数 | F21: 収穫量（kｇ） | G21: 株数 | H21: 面積（㎡） | I21: 1株収量（ｇ） | J21: 歩留まり（％）
B22: かおり野 | C22: 42.16 | D22: 18.93 | E22: 323 | F22: 61.09 | G22: 360 | H22: 16.8 | I22: 169.69444 | J22: 69.012932
B23: よつぼし | C23: 45.15 | D23: 40.74 | E23: 306 | F23: 85.88 | G23: 360 | H23: 17 | I23: 238.56667 | J23: 52.569745
B24: やよいひめ | C24: 65.67 | D24: 46.73 | E24: 510 | F24: 112.04 | G24: 700 | H24: 34 | I24: 160.05429 | J24: 58.612257
B25: 紅ほっぺ | C25: 181.15 | D25: 111.52 | E25: 1231 | F25: 292.67 | G25: 1830 | H25: 134.2 | I25: 159.92623 | J25: 61.895341
B26: 平均 | C26: 83.53 | D26: 54.39 | E26: 592.5 | F26: 137.92 | G26: 812.5 | H26: 50.5 | I26: 182.06041 | J26: 60.522569
B27: 中央値 | C27: 55.41 | D27: 43.55 | E27: 416.5 | F27: 98.96 | G27: 530 | H27: 25.5 | I27: 164.87437 | J27: 60.253799

Sheet Sheet1
A1: 品種名 | B1: 正規品（kｇ） | C1: 収穫量（kｇ） | D1: 1株収量（ｇ） | E1: 歩留まり（％） | F1: パック数 | G1: 株数 | I1: 品種名/正規品（ｇ） | N1: 品種名/加工品（ｇ） | S1: 品種名/パック数 | X1: 品種名/収量
A2: かおり野 | B2: 42.16 | C2: 61.09 | D2: 169.69444 | E2: 69.012932 | F2: 323 | G2: 360 | I2: かおり野 | J2: よつぼし | K2: やよいひめ | L2: 紅ほっぺ | N2: かおり野 | O2: よつぼし | P2: やよいひめ | Q2: 紅ほっぺ | S2: かおり野 | T2: よつぼし | U2: やよいひめ | V2: 紅ほっぺ | X2: かおり野 | Y2: よつぼし | Z2: やよいひめ | AA2: 紅ほっぺ
A3: よつぼし | B3: 45.15 | C3: 85.88 | D3: 238.56667 | E3: 52.569745 | F3: 306 | G3: 360 | I3: 240 | J3: 46 | K3: 800 | L3: 100 | N3: 0 | O3: 0 | P3: 0 | Q3: 0 | S3: 3 | T3: 0 | U3: 7 | V3: 0 | X3: =(I3+N3) -> 240 | Y3: =(J3+O3) -> 46 | Z3: =(K3+P3) -> 800 | AA3: =(L3+Q3) -> 100
A4: やよいひめ | B4: 65.67 | C4: 112.04 | D4: 160.05429 | E4: 58.612257 | F4: 510 | G4: 700 | I4: 1510 | J4: 0 | K4: 300 | L4: 100 | N4: 0 | O4: 200 | P4: 0 | Q4: 0 | S4: 12 | T4: 0 | U4: 1 | V4: 1 | X4: =(I4+N4) -> 1510 | Y4: =(J4+O4) -> 200 | Z4: =(K4+P4) -> 300 | AA4: =(L4+Q4) -> 100
A5: 紅ほっぺ | B5: 181.15 | C5: 292.67 | D5: 159.92623 | E5: 61.895341 | F5: 1231 | G5: 1830 | I5: 120 | J5: 240 | K5: 440 | L5: 46 | N5: 0 | O5: 0 | P5: 1240 | Q5: 0 | S5: 0 | T5: 0 | U5: 3 | V5: 0 | X5: =(I5+N5) -> 120 | Y5: =(J5+O5) -> 240 | Z5: =(K5+P5) -> 1680 | AA5: =(L5+Q5) -> 46
A6: 平均 | B6: 83.53 | C6: 137.92 | D6: 182.06041 | E6: 60.522569 | F6: 592.5 | G6: 812.5 | I6: 3340 | J6: 440 | K6: 220 | L6: 130 | N6: 0 | O6: 0 | P6: 300 | Q6: 0 | S6: 32 | T6: 4 | U6: 2 | V6: 0 | X6: =(I6+N6) -> 3340 | Y6: =(J6+O6) -> 440 | Z6: =(K6+P6) -> 520 | AA6: =(L6+Q6) -> 130
A7: 中央値 | B7: 55.41 | C7: 98.96 | D7: 164.87437 | E7: 60.253799 | F7: 416.5 | G7: 530 | I7: 240 | J7: 220 | K7: 1820 | L7: 100 | N7: 0 | O7: 0 | P7: 158 | Q7: 0 | S7: 0 | T7: 0 | U7: 15 | V7: 0 | X7: =(I7+N7) -> 240 | Y7: =(J7+O7) -> 220 | Z7: =(K7+P7) -> 1978 | AA7: =(L7+Q7) -> 100
I8: 5140 | J8: 960 | K8: 260 | L8: 320 | N8: 0 | O8: 560 | P8: 110 | Q8: 0 | S8: 31 | T8: 8 | U8: 1 | V8: 3 | X8: =(I8+N8) -> 5140 | Y8: =(J8+O8) -> 1520 | Z8: =(K8+P8) -> 370 | AA8: =(L8+Q8) -> 320
I9: 480 | J9: 500 | K9: 180 | L9: 260 | N9: 0 | O9: 0 | P9: 60 | Q9: 0 | S9: 0 | T9: 0 | U9: 1 | V9: 0 | X9: =(I9+N9) -> 480 | Y9: =(J9+O9) -> 500 | Z9: =(K9+P9) -> 240 | AA9: =(L9+Q9) -> 260
I10: 840 | J10: 160 | K10: 1680 | L10: 195 | N10: 0 | O10: 800 | P10: 1540 | Q10: 0 | S10: 0 | T10: 0 | U10: 12 | V10: 0 | X10: =(I10+N10) -> 840 | Y10: =(J10+O10) -> 960 | Z10: =(K10+P10) -> 3220 | AA10: =(L10+Q10) -> 195
I11: 1600 | J11: 880 | K11: 868 | L11: 170 | N11: 500 | O11: 0 | P11: 712 | Q11: 0 | S11: 15 | T11: 6 | U11: 7 | V11: 0 | X11: =(I11+N11) -> 2100 | Y11: =(J11+O11) -> 880 | Z11: =(K11+P11) -> 1580 | AA11: =(L11+Q11) -> 170
I12: 300 | J12: 1240 | K12: 120 | L12: 320 | N12: 0 | O12: 0 | P12: 60 | Q12: 0 | S12: 0 | T12: 10 | U12: 1 | V12: 0 | X12: =(I12+N12) -> 300 | Y12: =(J12+O12) -> 1240 | Z12: =(K12+P12) -> 180 | AA12: =(L12+Q12) -> 320
I13: 4700 | J13: 500 | K13: 1200 | L13: 200 | N13: 0 | O13: 0 | P13: 1640 | Q13: 0 | S13: 42 | T13: 2 | U13: 11 | V13: 0 | X13: =(I13+N13) -> 4700 | Y13: =(J13+O13) -> 500 | Z13: =(K13+P13) -> 2840 | AA13: =(L13+Q13) -> 200
I14: 220 | J14: 1880 | K14: 1370 | L14: 540 | N14: 0 | O14: 2480 | P14: 1430 | Q14: 0 | S14: 1 | T14: 10 | U14: 11 | V14: 3 | X14: =(I14+N14) -> 220 | Y14: =(J14+O14) -> 4360 | Z14: =(K14+P14) -> 2800 | AA14: =(L14+Q14) -> 540
I15: 1460 | J15: 210 | K15: 0 | L15: 80 | N15: 0 | O15: 330 | P15: 0 | Q15: 0 | S15: 12 | T15: 2 | U15: 0 | V15: 0 | X15: =(I15+N15) -> 1460 | Y15: =(J15+O15) -> 540 | Z15: =(K15+P15) -> 0 | AA15: =(L15+Q15) -> 80
I16: 520 | J16: 2036 | K16: 1060 | L16: 260 | N16: 0 | O16: 435 | P16: 2560 | Q16: 0 | S16: 2 | T16: 15 | U16: 8 | V16: 0 | X16: =(I16+N16) -> 520 | Y16: =(J16+O16) -> 2471 | Z16: =(K16+P16) -> 3620 | AA16: =(L16+Q16) -> 260
I17: 820 | J17: 220 | K17: 1160 | L17: 120 | N17: 822 | O17: 120 | P17: 1600 | Q17: 0 | S17: 8 | T17: 1 | U17: 9 | V17: 0 | X17: =(I17+N17) -> 1642 | Y17: =(J17+O17) -> 340 | Z17: =(K17+P17) -> 2760 | AA17: =(L17+Q17) -> 120
I18: 128 | J18: 1990 | K18: 0 | L18: 120 | N18: 282 | O18: 1250 | P18: 0 | Q18: 0 | S18: 1 | T18: 17 | U18: 0 | V18: 0 | X18: =(I18+N18) -> 410 | Y18: =(J18+O18) -> 3240 | Z18: =(K18+P18) -> 0 | AA18: =(L18+Q18) -> 120
I19: 1880 | J19: 260 | K19: 600 | L19: 80 | N19: 665 | O19: 60 | P19: 1760 | Q19: 0 | S19: 9 | T19: 1 | U19: 5 | V19: 0 | X19: =(I19+N19) -> 2545 | Y19: =(J19+O19) -> 320 | Z19: =(K19+P19) -> 2360 | AA19: =(L19+Q19) -> 80
... I54: 80 | J54: 1420 | K54: 600 | L54: 2840 | N54: 0 | O54: 0 | P54: 0 | Q54: 1020 | S54: 0 | T54: 2 | U54: 4 | V54: 26 | X54: =(I54+N54) -> 80 | Y54: =(J54+O54) -> 1420 | Z54: =(K54+P54) -> 600 | AA54: =(L54+Q54) -> 3860
K55: 200 | L55: 1620 | P55: 120 | Q55: 450 | U55: 2 | V55: 0 | X55: =(I55+N55) -> 0 | Y55: =(J55+O55) -> 0 | Z55: =(K55+P55) -> 320 | AA55: =(L55+Q55) -> 2070
K56: 340 | L56: 880 | P56: 220 | Q56: 94 | U56: 3 | V56: 7 | X56: =(I56+N56) -> 0 | Y56: =(J56+O56) -> 0 | Z56: =(K56+P56) -> 560 | AA56: =(L56+Q56) -> 974
K57: 3100 | L57: 1080 | P57: 510 | Q57: 430 | U57: 31 | V57: 5 | X57: =(I57+N57) -> 0 | Y57: =(J57+O57) -> 0 | Z57: =(K57+P57) -> 3610 | AA57: =(L57+Q57) -> 1510
K58: 1020 | L58: 1480 | P58: 0 | Q58: 0 | U58: 7 | V58: 12 | X58: =(I58+N58) -> 0 | Y58: =(J58+O58) -> 0 | Z58: =(K58+P58) -> 1020 | AA58: =(L58+Q58) -> 1480
K59: 1760 | L59: 810 | P59: 620 | Q59: 660 | U59: 15 | V59: 6 | X59: =(I59+N59) -> 0 | Y59: =(J59+O59) -> 0 | Z59: =(K59+P59) -> 2380 | AA59: =(L59+Q59) -> 1470
K60: 2960 | L60: 600 | P60: 360 | Q60: 90 | U60: 26 | V60: 5 | X60: =(I60+N60) -> 0 | Y60: =(J60+O60) -> 0 | Z60: =(K60+P60) -> 3320 | AA60: =(L60+Q60) -> 690
K61: 4170 | L61: 2500 | P61: 1400 | Q61: 760 | U61: 40 | V61: 16 | X61: =(I61+N61) -> 0 | Y61: =(J61+O61) -> 0 | Z61: =(K61+P61) -> 5570 | AA61: =(L61+Q61) -> 3260
K62: 100 | L62: 820 | P62: 200 | Q62: 747 | U62: 1 | V62: 8 | X62: =(I62+N62) -> 0 | Y62: =(J62+O62) -> 0 | Z62: =(K62+P62) -> 300 | AA62: =(L62+Q62) -> 1567
K63: 220 | L63: 0 | P63: 1120 | Q63: 0 | U63: 2 | V63: 0 | X63: =(I63+N63) -> 0 | Y63: =(J63+O63) -> 0 | Z63: =(K63+P63) -> 1340 | AA63: =(L63+Q63) -> 0
K64: 1010 | L64: 480 | P64: 450 | Q64: 100 | U64: 7 | V64: 3 | X64: =(I64+N64) -> 0 | Y64: =(J64+O64) -> 0 | Z64: =(K64+P64) -> 1460 | AA64: =(L64+Q64) -> 580
K65: 680 | L65: 460 | P65: 0 | Q65: 440 | U65: 5 | V65: 4 | X65: =(I65+N65) -> 0 | Y65: =(J65+O65) -> 0 | Z65: =(K65+P65) -> 680 | AA65: =(L65+Q65) -> 900
K66: 0 | L66: 1800 | P66: 800 | Q66: 0 | U66: 0 | V66: 8 | X66: =(I66+N66) -> 0 | Y66: =(J66+O66) -> 0 | Z66: =(K66+P66) -> 800 | AA66: =(L66+Q66) -> 1800
... K75: 80 | L75: 1960 | P75: 0 | Q75: 880 | U75: 0 | V75: 18 | X75: =(I75+N75) -> 0 | Y75: =(J75+O75) -> 0 | Z75: =(K75+P75) -> 80 | AA75: =(L75+Q75) -> 2840
L76: 114 | Q76: 366 | V76: 1 | X76: =(I76+N76) -> 0 | Y76: =(J76+O76) -> 0 | Z76: =(K76+P76) -> 0 | AA76: =(L76+Q76) -> 480
L77: 500 | Q77: 320 | V77: 0 | X77: =(I77+N77) -> 0 | Y77: =(J77+O77) -> 0 | Z77: =(K77+P77) -> 0 | AA77: =(L77+Q77) -> 820
L78: 420 | Q78: 260 | V78: 4 | X78: =(I78+N78) -> 0 | Y78: =(J78+O78) -> 0 | Z78: =(K78+P78) -> 0 | AA78: =(L78+Q78) -> 680
L79: 0 | Q79: 0 | V79: 0 | X79: =(I79+N79) -> 0 | Y79: =(J79+O79) -> 0 | Z79: =(K79+P79) -> 0 | AA79: =(L79+Q79) -> 0
L80: 2300 | Q80: 2707 | V80: 23 | X80: =(I80+N80) -> 0 | Y80: =(J80+O80) -> 0 | Z80: =(K80+P80) -> 0 | AA80: =(L80+Q80) -> 5007
L81: 1468 | Q81: 332 | V81: 12 | X81: =(I81+N81) -> 0 | Y81: =(J81+O81) -> 0 | Z81: =(K81+P81) -> 0 | AA81: =(L81+Q81) -> 1800
L82: 0 | Q82: 0 | V82: 0 | X82: =(I82+N82) -> 0 | Y82: =(J82+O82) -> 0 | Z82: =(K82+P82) -> 0 | AA82: =(L82+Q82) -> 0
...

Sheet 品収
A1: 期間１０月２５日～６月１１日
A2: 品種名 | B2: 収量（ｇ） | C2: 加工用（ｇ） | D2: パック数 | F2: 品種名 | G2: 収量（ｇ） | H2: 加工用（ｇ） | I2: パック数 | K2: 品種名 | L2: 収量（ｇ） | M2: 加工用（ｇ） | N2: パック数 | P2: 品種名 | Q2: 収量（ｇ） | R2: 加工用（ｇ） | S2: パック数 | V2: FILTER(E4:H447,ISNUMBER(SEARCH("かおり",E4:E447)))
A3: {=_xlfn._xlws.FILTER(元!E4:H447,ISNUMBER(SEARCH("かおり",元!E4:E447)))} -> かおり野 | B3: 240 | C3: 0 | D3: 3 | F3: {=_xlfn._xlws.FILTER(元!E4:H447,ISNUMBER(SEARCH("よつぼし",元!E4:E447)))} -> よつぼし | G3: 46 | H3: 0 | I3: 0 | K3: {=_xlfn._xlws.FILTER(元!E4:H447,ISNUMBER(SEARCH("やよい",元!E4:E447)))} -> やよい姫 | L3: 800 | M3: 0 | N3: 7 | P3: {=_xlfn._xlws.FILTER(元!E4:H447, (ISNUMBER(SEARCH("紅",元!E4:E447))) + (ISNUMBER(SEARCH("無",元!E4:E447 ))) )} -> 紅ほっぺ（断） | Q3: 100 | R3: 0 | S3: 0 | V3: FILTER(元データ!D4:H447, 元データ!D4:D447="ケイアイ")
A4: かおり野 | B4: 1510 | C4: 0 | D4: 12 | F4: よつぼし | G4: 0 | H4: 200 | I4: 0 | K4: やよい姫 | L4: 300 | M4: 0 | N4: 1 | P4: 紅ほっぺ(断） | Q4: 100 | R4: 0 | S4: 1 | V4: FILTER(D4:H447, (ISNUMBER(SEARCH("マルテー", F4:F447))) + (ISNUMBER(SEARCH("ホシ", F4:F447))) )
A5: かおり野 | B5: 120 | C5: 0 | D5: 0 | F5: よつぼし | G5: 240 | H5: 0 | I5: 0 | K5: やよい姫 | L5: 440 | M5: 1240 | N5: 3 | P5: 紅ほっぺ（断） | Q5: 46 | R5: 0 | S5: 0
A6: かおり野 | B6: 3340 | C6: 0 | D6: 32 | F6: よつぼし | G6: 440 | H6: 0 | I6: 4 | K6: やよい姫 | L6: 220 | M6: 300 | N6: 2 | P6: 紅ほっぺ（断） | Q6: 130 | R6: 0 | S6: 0
A7: かおり野 | B7: 240 | C7: 0 | D7: 0 | F7: よつぼし | G7: 220 | H7: 0 | I7: 0 | K7: やよいひめ | L7: 1820 | M7: 158 | N7: 15 | P7: 紅ほっぺ（断） | Q7: 100 | R7: 0 | S7: 0
A8: かおり野 | B8: 5140 | C8: 0 | D8: 31 | F8: よつぼし | G8: 960 | H8: 560 | I8: 8 | K8: やよいひめ | L8: 260 | M8: 110 | N8: 1 | P8: 紅ほっぺ（断） | Q8: 320 | R8: 0 | S8: 3
A9: かおり野 | B9: 480 | C9: 0 | D9: 0 | F9: よつぼし | G9: 500 | H9: 0 | I9: 0 | K9: やよいひめ | L9: 180 | M9: 60 | N9: 1 | P9: 紅ほっぺ（断） | Q9: 260 | R9: 0 | S9: 0
A10: かおり野 | B10: 840 | C10: 0 | D10: 0 | F10: よつぼし | G10: 160 | H10: 800 | I10: 0 | K10: やよいひめ | L10: 1680 | M10: 1540 | N10: 12 | P10: 紅ほっぺ（断） | Q10: 195 | R10: 0 | S10: 0
A11: かおり野 | B11: 1600 | C11: 500 | D11: 15 | F11: よつぼし | G11: 880 | H11: 0 | I11: 6 | K11: やよいひめ | L11: 868 | M11: 712 | N11: 7 | P11: 紅ほっぺ（断） | Q11: 170 | R11: 0 | S11: 0
A12: かおり野 | B12: 300 | C12: 0 | D12: 0 | F12: よつぼし | G12: 1240 | H12: 0 | I12: 10 | K12: やよいひめ | L12: 120 | M12: 60 | N12: 1 | P12: 紅ほっぺ（断） | Q12: 320 | R12: 0 | S12: 0
A13: かおり野 | B13: 4700 | C13: 0 | D13: 42 | F13: よつぼし | G13: 500 | H13: 0 | I13: 2 | K13: やよいひめ | L13: 1200 | M13: 1640 | N13: 11 | P13: 紅ほっぺ（断） | Q13: 200 | R13: 0 | S13: 0
A14: かおり野 | B14: 220 | C14: 0 | D14: 1 | F14: よつぼし | G14: 1880 | H14: 2480 | I14: 10 | K14: やよいひめ | L14: 1370 | M14: 1430 | N14: 11 | P14: 紅ほっぺ（断） | Q14: 540 | R14: 0 | S14: 3
A15: かおり野 | B15: 1460 | C15: 0 | D15: 12 | F15: よつぼし | G15: 210 | H15: 330 | I15: 2 | K15: やよいひめ | L15: 0 | M15: 0 | N15: 0 | P15: 紅ほっぺ | Q15: 80 | R15: 0 | S15: 0
A16: かおり野 | B16: 520 | C16: 0 | D16: 2 | F16: よつぼし | G16: 2036 | H16: 435 | I16: 15 | K16: やよいひめ | L16: 1060 | M16: 2560 | N16: 8 | P16: 紅ほっぺ（断） | Q16: 260 | R16: 0 | S16: 0
... A54: かおりの | B54: 80 | C54: 0 | D54: 0 | F54: よつぼし | G54: 1420 | H54: 0 | I54: 2 | K54: やよいひめ | L54: 600 | M54: 0 | N54: 4 | P54: 紅ほっぺ（無） | Q54: 2840 | R54: 1020 | S54: 26
K55: やよいひめ | L55: 200 | M55: 120 | N55: 2 | P55: 紅ほっぺ | Q55: 1620 | R55: 450 | S55: 0
K56: やよいひめ | L56: 340 | M56: 220 | N56: 3 | P56: 紅ほっぺ | Q56: 880 | R56: 94 | S56: 7
K57: やよいひめ | L57: 3100 | M57: 510 | N57: 31 | P57: 紅ほっぺ | Q57: 1080 | R57: 430 | S57: 5
K58: やよいひめ | L58: 1020 | M58: 0 | N58: 7 | P58: 紅ほっぺ | Q58: 1480 | R58: 0 | S58: 12
K59: やよいひめ | L59: 1760 | M59: 620 | N59: 15 | P59: 紅ほっぺ（無） | Q59: 810 | R59: 660 | S59: 6
K60: やよいひめ | L60: 2960 | M60: 360 | N60: 26 | P60: 紅ほっぺ | Q60: 600 | R60: 90 | S60: 5
K61: やよいひめ | L61: 4170 | M61: 1400 | N61: 40 | P61: 紅ほっぺ | Q61: 2500 | R61: 760 | S61: 16
K62: やよいひめ | L62: 100 | M62: 200 | N62: 1 | P62: 紅ほっぺ | Q62: 820 | R62: 747 | S62: 8
K63: やよいひめ | L63: 220 | M63: 1120 | N63: 2 | P63: 紅ほっぺ | Q63: 0 | R63: 0 | S63: 0
K64: やよいひめ | L64: 1010 | M64: 450 | N64: 7 | P64: 紅ほっぺ（無） | Q64: 480 | R64: 100 | S64: 3
K65: やよいひめ | L65: 680 | M65: 0 | N65: 5 | P65: 紅ほっぺ（無） | Q65: 460 | R65: 440 | S65: 4
K66: やよいひめ | L66: 0 | M66: 800 | N66: 0 | P66: 紅ほっぺ（無） | Q66: 1800 | R66: 0 | S66: 8
... K75: やよいひめ | L75: 80 | M75: 0 | N75: 0 | P75: 紅ほっぺ | Q75: 1960 | R75: 880 | S75: 18
P76: 紅ほっぺ | Q76: 114 | R76: 366 | S76: 1
P77: 紅ほっぺ | Q77: 500 | R77: 320 | S77: 0
P78: 紅ほっぺ（無） | Q78: 420 | R78: 260 | S78: 4
P79: 紅ほっぺ（無） | Q79: 0 | R79: 0 | S79: 0
P80: 紅ほっぺ（無） | Q80: 2300 | R80: 2707 | S80: 23
P81: 紅ほっぺ（無） | Q81: 1468 | R81: 332 | S81: 12
P82: 紅ほっぺ | Q82: 0 | R82: 0 | S82: 0
P83: 紅ほっぺ（無） | Q83: 3480 | R83: 460 | S83: 32
P84: 紅ほっぺ | Q84: 320 | R84: 180 | S84: 3
P85: 紅ほっぺ | Q85: 220 | R85: 180 | S85: 2
...

Sheet 元
C1: 断＝窒素断 | D1: 無＝無仮植え | J1: FILTER(E4:H447,ISNUMBER(SEARCH("かおり",E4:E447)))
J2: FILTER(元データ!D4:H447, 元データ!D4:D447="ケイアイ")
B3: 月日 | C3: ハウス棟 | D3: 企業名 | E3: 品種名 | F3: 収量（ｇ） | G3: 加工用（ｇ） | H3: パック数 | J3: FILTER(D4:H447, (ISNUMBER(SEARCH("マルテー", F4:F447))) + (ISNUMBER(SEARCH("ホシ", F4:F447))) )
B4: 45955 | C4: 実験棟 | D4: マルテー | E4: 紅ほっぺ（断） | F4: 100 | G4: 0 | H4: 0
B5: 45961 | C5: B棟 | D5: 三和 | E5: 紅ほっぺ(断） | F5: 100 | G5: 0 | H5: 1
B6: 45966 | C6: B棟 | D6: 三和 | E6: 紅ほっぺ（断） | F6: 46 | G6: 0 | H6: 0
B7: 45967 | C7: 実験棟 | D7: マルテー | E7: 紅ほっぺ（断） | F7: 130 | G7: 0 | H7: 0
B8: 45967 | C8: E棟 | D8: マルテー | E8: 紅ほっぺ（断） | F8: 100 | G8: 0 | H8: 0
B9: 45975 | C9: 実験棟 | D9: マルテー | E9: 紅ほっぺ（断） | F9: 320 | G9: 0 | H9: 3
B10: 45975 | C10: E棟 | D10: マルテー | E10: 紅ほっぺ（断） | F10: 260 | G10: 0 | H10: 0
B11: 45983 | C11: B棟棟 | D11: QB | E11: 紅ほっぺ（断） | F11: 195 | G11: 0 | H11: 0
B12: 45986 | C12: A棟 | D12: 東レ | E12: 紅ほっぺ（断） | F12: 170 | G12: 0 | H12: 0
B13: 45989 | C13: B棟 | D13: Adobe | E13: かおり野 | F13: 240 | G13: 0 | H13: 3
B14: 45989 | C14: 実験棟 | D14: マルテー | E14: 紅ほっぺ（断） | F14: 320 | G14: 0 | H14: 0
B15: 45996 | C15: B棟 | D15: Adobe | E15: かおり野 | F15: 1510 | G15: 0 | H15: 12
... B38: 46017 | C38: 実験棟 | D38: マルテー | E38: 紅ほっぺ（断） | F38: 120 | G38: 0 | H38: 0
B39: 46017 | D39: マルテー | E39: かおり野 | F39: 300 | G39: 0 | H39: 0
B40: 46017 | D40: マルテー | E40: よつぼし | F40: 500 | G40: 0 | H40: 0
B41: 45665 | C41: B棟 | D41: QB | E41: 紅ほっぺ（断） | F41: 320 | G41: 0 | H41: 0
B42: 45665 | D42: NaITO | E42: 紅ほっぺ（断） | F42: 60 | G42: 0 | H42: 0
B43: 45665 | D43: ソリトン | E43: 紅ほっぺ | F43: 960 | G43: 0 | H43: 5
B44: 45665 | D44: 三和 | E44: 紅ほっぺ（断） | F44: 240 | G44: 0 | H44: 0
B45: 45666 | C45: A棟 | D45: 東レ | E45: 紅ほっぺ | F45: 3940 | G45: 0 | H45: 28
B46: 45666 | C46: B棟 | D46: 東レ | E46: よつぼし | F46: 160 | G46: 800 | H46: 0
B47: 45666 | D47: 昭和女子 | E47: 紅ほっぺ | F47: 340 | G47: 0 | H47: 0
B48: 45666 | D48: QB | E48: 紅ほっぺ（断） | F48: 100 | G48: 0 | H48: 0
B49: 45666 | D49: バリュ | E49: 紅ほっぺ | F49: 1140 | G49: 0 | H49: 0
B50: 45666 | D50: Adobe | E50: かおり野 | F50: 4700 | G50: 0 | H50: 42
B51: 45666 | C51: 実験棟 | D51: マルテー | E51: 紅ほっぺ（断） | F51: 1120 | G51: 0 | H51: 10
B52: 45666 | D52: マルテー | E52: よつぼし | F52: 880 | G52: 0 | H52: 6
B53: 45666 | D53: マルテー | E53: かおり野 | F53: 220 | G53: 0 | H53: 1
B54: 45672 | C54: B棟 | D54: 昭和女子 | E54: 紅ほっぺ | F54: 600 | G54: 0 | H54: 5
B55: 45672 | D55: QB | E55: 紅ほっぺ（断） | F55: 300 | G55: 0 | H55: 1
B56: 45672 | D56: ソリトン | E56: 紅ほっぺ | F56: 980 | G56: 0 | H56: 8
B57: 45672 | D57: 岡部 | E57: 紅ほっぺ | F57: 500 | G57: 0 | H57: 3
B58: 45672 | D58: 三和 | E58: 紅ほっぺ（断） | F58: 380 | G58: 0 | H58: 2
B59: 45672 | D59: NaITO | E59: 紅ほっぺ（断） | F59: 1480 | G59: 0 | H59: 13
B60: 45672 | D60: ケイアイ | E60: 紅ほっぺ | F60: 1500 | G60: 0 | H60: 13
B61: 45672 | D61: 日建 | E61: 紅ほっぺ（断） | F61: 420 | G61: 0 | H61: 3
B62: 45672 | D62: 富士機械 | E62: やよい姫 | F62: 800 | G62: 0 | H62: 7
...

Sheet 企コ
A1: ✅【1】全体傾向と代表値の確認 | N1: 📊【1】分析の目的
A3: 指標 | B3: 平均（代表値） | C3: 中央値 | D3: 最大 | E3: 最小 | N3: このデータは、企業（栽培者）ごとの生産性・品質・品種ごとの収量特性などを比較できる形式です。以下を主に見ていきます：
A4: 正規品収量（g） | B4: 339,970（合計） | C4: 12480 | D4: 77893 | E4: 2616
A5: 加工用収量（g） | B5: 228,265（合計） | C5: 7843 | D5: 58668 | E5: 2509 | N5: 株あたり収量（生産性）
A6: パック数 | B6: 2,399（合計） | C6: 92 | D6: 478 | E6: 9
A7: 総収穫量（g） | B7: 568,235（合計） | C7: 18187 | D7: 136561 | E7: 5516 | N7: 歩留まり（正規品の比率＝品質）
A8: 1株あたり収量（g） | B8: - | C8: 147.85（中央値） | D8: 250.1 | E8: 68.95
A9: 歩留まり（%） | B9: - | C9: 0.6074 | D9: 74.38 | E9: 47.43 | N9: 加工比率（出荷ロスの程度）
A10: 加工比率（%） | B10: - | C10: 0.3926 | D10: 52.57 | E10: 25.62
A11: 10aあたり収量（kg） | B11: - | C11: 216.51kg | D11: 446.62 | E11: 65.67 | N11: 10aあたり収量（面積当たりの収量性）
A13: 🔎 読み取りポイント： | N13: 品種や企業ごとの傾向
A15: 正規品・加工用・収穫量すべてにおいてばらつきが大きく、標準偏差も高い（例：収穫量＝±38,347g）。 | N15: 統計的に見たパフォーマンス差（分散・標準偏差）
A17: 1株あたり収量の中央値147.85gは、砂栽培の目標（250～300g）より低く、理想値（400g～）からは大きく離れる。
A19: 歩留まりは60%前後が中央値。加工率は約40%。 | N19: 🧮【2】指標別の統計的読み取り
N21: ✅ ① 1株あたり収量（生産性）
A23: ✅【2】1株あたり収量（250g目標との比較） | N23: 統計量 | O23: 値
N24: 平均 | O24: 約 157.9g
A25: 企業 | B25: 品種 | C25: 1株収量（g） | D25: 評価（目標250g比） | N25: 中央値 | O25: 147.85g
A26: マルテー | B26: 4種 | C26: 250.1 | D26: ✅ 目標達成！ | N26: 最大値 | O26: 250.10g（マルテー）
A27: 東レ | B27: 紅ほ＋よつぼし | C27: 213.38 | D27: ◯ 優秀 | N27: 最小値 | O27: 68.95g（三和）
A28: NaITO | B28: 紅ほっぺ | C28: 217.98 | D28: ◯ 優秀 | N28: 標準偏差 | O28: 53.50g（ばらつき大）
A29: ソリトン | B29: 紅ほっぺ | C29: 227.34 | D29: ◯ 優秀
A30: 昭和女子 | B30: 紅ほっぺ | C30: 149.3 | D30: ❌ 不足（約100g差） | N30: 🔎 **マルテー（250.1g）**が最も生産性が高く、**三和（68.95g）**が最も低い。全体のばらつきが大きいため、統計的に有意な差があると判断可能。
A31: 日建 | B31: 紅ほっぺ | C31: 88.86 | D31: ❌ かなり低い
A32: 三和 | B32: 紅ほっぺ | C32: 68.95 | D32: ❌ 最低値
A34: 🔎 読み取りポイント： | N34: ✅ ② 歩留まり（正規品比率）
A36: マルテーが唯一250gを超えており、好記録に最も近い。 | N36: 統計量 | O36: 値
N37: 平均 | O37: 約 60.6%
A38: ソリトン、NaITO、東レなども目標に近く、管理が良好と考えられる。 | N38: 中央値 | O38: 0.6074
N39: 最大値 | O39: 74.38%（ケイアイ）
A40: 一方、多くの企業が200g未満であり、栽培管理・密度・環境に改善余地あり。 | N40: 最小値 | O40: 47.43%（三和）
N41: 標準偏差 | O41: 7.13%（中程度）
N43: 🔎 歩留まりの観点では、ケイアイが最も良質な果実を多く確保。三和や昭和女子などは半数近くが加工用であり、品質面の課題がある可能性あり。
A44: ✅【3】歩留まり（正規品率）と加工比率の評価
A46: 企業 | B46: 歩留まり（%） | C46: 評価 | D46: コメント
A47: ケイアイ | B47: 74.38 | C47: ◎ | D47: 非常に高品質 | N47: ✅ ③ 加工比率（ロス率）
A48: Adobe | B48: 69.01 | C48: ◎ | D48: 品質良好
A49: ソリトン | B49: 68.62 | C49: ◎ | D49: 加工用少なく優秀 | N49: 統計量 | O49: 値
A50: 日建 | B50: 64.71 | C50: ◯ | D50: 安定品質 | N50: 平均 | O50: 約 39.4%
A51: 東レ | B51: 57.04 | C51: △ | D51: 標準程度 | N51: 中央値 | O51: 0.3926
...

Sheet 品コ
A1: ✅ 1. 1株あたり収量の比較と評価（栽培目安との比較） | N1: 🔍【1】データの再構成と計算
A3: 品種名 | B3: 1株あたり収量（g） | C3: 栽培方法 | D3: 目安（g/株） | E3: 評価 | N3: まず、**1株あたり収量（g）**を計算し、比較しやすくします。
A4: かおり野 | B4: 169.69 | C4: 高設砂栽培 | D4: 250～350 | E4: ❌ 目安を大きく下回る
A5: よつぼし | B5: 238.57 | C5: 高設砂栽培 | D5: 250～350 | E5: △ やや下回るが良好 | N5: 品種名 | O5: 収穫量（g） | P5: 株数 | Q5: 1株あたり収量（g）
A6: やよいひめ | B6: 160.05 | C6: 高設砂栽培 | D6: 250～350 | E6: ❌ 目安を大きく下回る | N6: かおり野 | O6: 61090 | P6: 360 | Q6: 169.69
A7: 紅ほっぺ | B7: 159.93 | C7: 土耕栽培 | D7: 150～250 | E7: ✅ 範囲内（やや下限） | N7: よつぼし | O7: 85884 | P7: 360 | Q7: 238.57
N8: やよいひめ | O8: 112038 | P8: 700 | Q8: 160.05
A9: 🔎 読み取りポイント： | N9: 紅ほっぺ | O9: 292665 | P9: 1830 | Q9: 159.93
A11: 高設砂栽培の「かおり野」「やよいひめ」は、目安をかなり下回っている → 栽培条件や管理、品種特性に課題がある可能性。
N12: 📊【2】分散分析（ANOVA）
A13: 「よつぼし」は目安に近い好成績。
N14: 目的：
A15: 「紅ほっぺ」は土耕栽培の基準内で適正。
N16: 「1株あたり収量」に品種間で統計的な差があるかを確認
N18: 結果（簡易的な計算によるANOVA）：
A19: ✅ 2. 品質の評価：歩留まり（正規品割合）と加工比率
N20: **群間のばらつき（SSB）**は大きくない（紅ほっぺ・やよいひめ・かおり野が似通っている）
A21: 品種名 | B21: 歩留まり（％） | C21: 加工比率（％） | D21: 評価
A22: かおり野 | B22: 69.01 | C22: 30.99 | D22: ◎ 最も高品質 | N22: よつぼしのみ明らかに収量が高く、分散の元になっている主な要因
A23: よつぼし | B23: 52.57 | C23: 47.43 | D23: ❌ 加工向け多め
A24: やよいひめ | B24: 58.61 | C24: 41.39 | D24: △ 中間程度 | N24: よって：
A25: 紅ほっぺ | B25: 61.9 | C25: 38.1 | D25: ◯ 標準的品質
N26: ✅ 「よつぼし」は他の品種より有意に1株あたり収量が高い可能性がある。
A27: 🔎 読み取りポイント：
A29: かおり野は高品質な果実が多く、歩留まりが非常に良い。
N30: 🧪【3】多重比較（Tukey's HSD法 近似）
A31: よつぼしは収量は多いが品質面ではやや劣る（加工品向けが多い）。
N32: Tukey法の代わりに概算で差を比較：
A33: 紅ほっぺ・やよいひめはその中間。
N34: 比較対象 | O34: 収量差（g） | P34: 差の特徴
N35: よつぼし − 紅ほっぺ | O35: 238.57 − 159.93 = +78.64g | P35: ✅ 有意差あり得る
N36: よつぼし − やよいひめ | O36: 238.57 − 160.05 = +78.52g | P36: ✅ 有意差あり得る
A37: ✅ 3. 10a（アール）あたり収量（kg）による面積効率の評価 | N37: よつぼし − かおり野 | O37: 238.57 − 169.69 = +68.88g | P37: ✅ 有意差あり得る
N38: やよいひめ − 紅ほっぺ | O38: 160.05 − 159.93 = 0.12g | P38: 差なし
A39: 品種名 | B39: 10aあたり収量（kg） | C39: 評価
A40: かおり野 | B40: 363.63 | C40: ◯ 高い | N40: → 「よつぼし」は明らかに他より収量が多い
A41: よつぼし | B41: 505.2 | C41: ◎ 非常に高い
A42: やよいひめ | B42: 329.52 | C42: △ 標準的
A43: 紅ほっぺ | B43: 218.08 | C43: ❌ 低め（栽培面積が広く非効率）
N44: 🔍【4】読み取れること（統計的な視点）
...

Sheet 方
B2: 期間１０月２５日～６月１１日
B3: 処理区名（紅ほっぺ） | C3: 正規品（ｇ） | D3: 加工用（ｇ） | E3: パック数 | F3: 収穫量（ｇ） | G3: 株数 | H3: 面積（㎡） | I3: 1株あたり収量（ｇ） | J3: 歩留まり（％） | K3: 加工比率（％） | L3: 10aあたり収量(kg)
B4: コントロール区 | C4: =SUM(方収!C3:C137) -> 70974 | D4: =SUM(方収!D3:D137) -> 35568 | E4: =SUM(方収!E3:E137) -> 526 | F4: =SUM(C4:D4) -> 106542 | G4: 560 | H4: 58.8 | I4: =F4/G4 -> 190.25357 | J4: =C4/F4*100 -> 66.615982 | K4: =D4/F4*100 -> 33.384018 | L4: =F4 /H4 * 100 / 1000 -> 181.19388
B5: 窒素断・無仮植処理区 | C5: =SUM(方収!H3:H129) -> 110072 | D5: =SUM(方収!I3:I129) -> 75951 | E5: =SUM(方収!J3:J129) -> 705 | F5: =SUM(C5:D5) -> 186023 | G5: 1270 | H5: 75.2 | I5: =F5/G5 -> 146.4748 | J5: =C5/F5*100 -> 59.171178 | K5: =D5/F5*100 -> 40.828822 | L5: =F5 /H5 * 100 / 1000 -> 247.37101
B6: 合計 | C6: =SUM(C4:C5) -> 181046 | D6: =SUM(D4:D5) -> 111519 | E6: =SUM(E4:E5) -> 1231 | F6: =SUM(F4:F5) -> 292565 | G6: =SUM(G4:G5) -> 1830 | H6: =SUM(H4:H5) -> 134 | I6: =SUM(I4:I5) -> 336.72837 | J6: =SUM(J4:J5) -> 125.78716 | ... L6: =SUM(L4:L5) -> 428.56489
B7: 平均 | C7: =AVERAGE(C4:C5) -> 90523 | D7: =AVERAGE(D4:D5) -> 55759.5 | E7: =AVERAGE(E4:E5) -> 615.5 | F7: =AVERAGE(F4:F5) -> 146282.5 | G7: =AVERAGE(G4:G5) -> 915 | H7: =AVERAGE(H4:H5) -> 67 | I7: =AVERAGE(I4:I5) -> 168.36419 | J7: =AVERAGE(J4:J5) -> 62.89358 | ... L7: =AVERAGE(L4:L5) -> 214.28244
